Workbook
Name \g: #REF!
Name \g: #REF!
Name \g: #REF!
Name \g: #REF!
Name \g: #REF!
Name ___________MES3: [1]DATOS!#REF!
Name ___________MES3: [1]DATOS!#REF!
Name ___________MES3: [1]DATOS!#REF!
Name ___________MES3: [1]DATOS!#REF!
Name ___________MES3: [1]DATOS!#REF!
Name ___________MES3: [1]DATOS!#REF!
Name ___________MES3: [1]DATOS!#REF!
Name __________MES3: [1]DATOS!#REF!
Name __________MES3: [1]DATOS!#REF!
Name __________MES3: [1]DATOS!#REF!
Name __________MES3: [1]DATOS!#REF!
Name __________MES3: [1]DATOS!#REF!
Name __________MES3: [1]DATOS!#REF!
Name __________MES3: [1]DATOS!#REF!
Name ________MES3: [1]DATOS!#REF!
Name ________MES3: [1]DATOS!#REF!
Name ________MES3: [1]DATOS!#REF!
Name ________MES3: [1]DATOS!#REF!
Name ________MES3: [1]DATOS!#REF!
Name ________MES3: [1]DATOS!#REF!
Name ________MES3: [1]DATOS!#REF!
Name _______MES3: [1]DATOS!#REF!
Name _______MES3: [1]DATOS!#REF!
Name _______MES3: [1]DATOS!#REF!
Name _______MES3: [1]DATOS!#REF!
Name _______MES3: [1]DATOS!#REF!
Name _______MES3: [1]DATOS!#REF!
Name _______MES3: [1]DATOS!#REF!
Name ______MES3: [1]DATOS!#REF!
Name _____MES1: [15]DATOS!$C$22
Name _____MES2: [1]DATOS!$C$24
Name ____MES1: [1]DATOS!$C$23
Name ____MES2: [1]DATOS!$C$24
Name ___LAS1: #REF!
Name ___LAS2: #REF!
Name ___MES1: [1]DATOS!$C$23
Name ___MES2: [1]DATOS!$C$24
Name ___MES3: [16]DATOS!$C$22
Name ___VMV1: #REF!
Name ___VMV2: #REF!
Name __LAS1: #REF!
Name __LAS2: #REF!
Name __MES1: [1]DATOS!$C$23
Name __MES2: [1]DATOS!$C$24
Name __MES3: [1]DATOS!#REF!
Name __MES3: [1]DATOS!#REF!
Name __MES3: [1]DATOS!#REF!
Name __MES3: [1]DATOS!#REF!
Name __MES3: [1]DATOS!#REF!
Name __MES3: [16]DATOS!$C$22
Name __VMV1: #REF!
Name __VMV2: #REF!
Name _LAS1: #REF!
Name _LAS2: #REF!
Name _MES1: [1]DATOS!$C$23

Sheet res %
A1: CUADRO DE CONTROL DE AVANCE DE METAS
A2: ITEM | B2: DESCRIPCION | C2: UND | D2: TOTAL | E2: ANTERIOR | G2: ACTUAL % | H2: ACUMULADO % | J2: SALDO
A3: =#REF! -> #REF! | B3: =#REF! -> #REF! | C3: GLB | G3: =+#REF! -> #REF! | H3: =#REF! -> #REF!
A4: 02 | B4: =+#REF! -> #REF! | C4: GLB | G4: =+#REF! -> #REF! | H4: =+#REF! -> #REF! | N4: 981176263
A5: 03 | B5: =#REF! -> #REF! | C5: GLB | G5: =+#REF! -> #REF! | H5: =+#REF! -> #REF! | I5: =#REF! -> #REF! | J5: =#REF! -> #REF! | K5: =#REF! -> #REF!
A6: 04 | B6: =#REF! -> #REF! | C6: GLB
A7: 05 | B7: =#REF! -> #REF! | C7: GLB
A8: 06 | B8: =#REF! -> #REF! | C8: GLB
A9: 07 | B9: =#REF! -> #REF! | C9: GLB | G9: =+#REF! -> #REF! | H9: =+#REF! -> #REF!
A10: 08 | B10: =#REF! -> #REF! | C10: GLB | G10: =+#REF! -> #REF! | H10: =+#REF! -> #REF!
A11: 09 | B11: =#REF! -> #REF! | C11: GLB | G11: =+#REF! -> #REF! | H11: =+#REF! -> #REF!
A12: 10 | B12: =#REF! -> #REF! | C12: GLB | G12: =+#REF! -> #REF! | H12: =+#REF! -> #REF!
A13: COSTO DIRECTO | D13: =SUM(#REF!) -> #REF! | F13: =SUM(#REF!) -> #REF! | G13: =+#REF! -> #REF! | H13: =+#REF! -> #REF! | I13: =SUM(#REF!) -> #REF! | K13: =SUM(#REF!) -> #REF! | L13: =+K13+I13 -> #REF!
L14: =+K14+I14 -> 0
A15: GASTOS GENERALES | D15: =ROUND(D13*#REF!,2) -> #REF! | F15: =ROUND(F13*#REF!,2) -> #REF! | I15: =ROUND(I13*#REF!,2) -> #REF! | K15: =ROUND(K13*#REF!,2) -> #REF! | L15: =+K15+I15 -> #REF!
L16: =+K16+I16 -> 0
A17: UTILIDADES | D17: =ROUND(D13*#REF!,2) -> #REF! | F17: =ROUND(F13*#REF!,2) -> #REF! | I17: =ROUND(I13*#REF!,2) -> #REF! | K17: =ROUND(K13*#REF!,2) -> #REF! | L17: =+K17+I17 -> #REF!
L18: =+K18+I18 -> 0
A19: SUB TOTAL | D19: =D13+D15+D17 -> #REF! | F19: =F13+F15+F17 -> #REF! | I19: =I13+I15+I17 -> #REF! | K19: =K13+K15+K17 -> #REF! | L19: =+K19+I19 -> #REF!
L20: =+K20+I20 -> 0
A21: FACTOR DE RELACIÓN | D21: =#REF!*D19 -> #REF! | F21: =ROUND(F19*#REF!,2) -> #REF! | I21: =ROUND(I19*#REF!,2) -> #REF! | K21: =ROUND(K19*#REF!,2) -> #REF! | L21: =+K21+I21 -> #REF!
K22: =+D22-I22 -> 0 | L22: =+K22+I22 -> 0
A23: I.G.V. | D23: =ROUND(D19*#REF!,2)-0.01 -> #REF! | F23: =ROUND(F21*#REF!,2) -> #REF! | I23: =ROUND(I21*#REF!,2) -> #REF! | K23: =ROUND(K21*#REF!,2)-0.01 -> #REF! | L23: =+K23+I23 -> #REF!
L24: =+K24+I24 -> 0
A25: VALORIZACION DE OBRA | D25: =D21+D23 -> #REF! | F25: =F23+F21 -> #REF! | I25: =I21+I23 -> #REF! | K25: =K21+K23 -> #REF! | L25: =+K25+I25 -> #REF!
L26: =+K26+I26 -> 0
A27: PORCENTAJE | D27: 1 | F27: =F25/D25 -> #REF! | K27: =+K25/D25 -> #REF! | L27: =+K27+H13 -> #REF!
L28: =+K28+I28 -> 0

Sheet FT
C2: FICHA TÉCNICA DEL PROYECTO
C3: A. DATOS GENERALES
C4: Entidad | D4: : | E4: MUNICIPALIDAD DISTRITAL DE PILLCO MARCA
C5: Obra | D5: : | E5: "MEJORAMIENTO Y AMPLIACIÓN DE LOS SERVICIOS DE TRANSITABILIDAD VEHICULAR Y PEATONAL DEL JR LOS PINOS Y JR LOS CEDROS EN CAYHUAYNA Y CAYHUAYNA DEL DISTRITO DE PILLCO MARCA - PROVINCIA DE HUÁNUCO - DEPARTAMENTO DE HUÁNUCO" con CUI N°2536252
C6: Código único de inversión | D6: : | E6: 2536252
C7: Aprobación del expediente técnico | D7: : | E7: RESOLUCIÓN DE GERENCIA N°125-2026-MDPM/GM
C8: Fecha de aprobación de expediente técnico | E8: 46120
C9: Fecha de presupuesto base | D9: : | E9: 46485
C10: Ubicación | D10: : | E10: DEPARTAMENTO: HUÁNUCO
E11: PROVINCIA: HUÁNUCO
E12: DISTRITO: PILLCO MARCA
E13: LOCALIDAD: CAYHUAYNA
C14: B. DEL CONTRATISTA EJECUTOR
C15: Ejecutor | D15: : | E15: CONSORCIO EJECUTOR LOS PINOS
C16: Representante común legal | D16: : | E16: SR. CALLUPE JARA KENEDY ISAAC
C17: Domicilio legal | D17: : | E17: BARRIO USHNOPATA N° S/N CP MENOR HUANCACHUPA -PILLCO MARCA -HUÁNUCO
C18: Proceso de selección | D18: : | E18: LICITACION PÚBLICA ABREVIADA DE OBRAS N°04-2026-MDPM/C-1
C19: Adjudicación de buena pro | D19: : | E19: 46175
C20: Contrato | D20: : | E20: CONTRATO DE EJECUCIÓN DE OBRA N°004-2026-MDPM/GM
C21: Fecha de firma del contrato | D21: : | E21: 46192
C22: Modalidad de ejecución | D22: : | E22: ADMINISTRACIÓN INDIRECTA - CONTRATA
C23: Sistema de contratación | D23: : | E23: PRECIOS UNITARIOS
C24: Valor referencial (con IGV) | D24: : | E24: 638827.47
C25: Monto del contrato principal (incl. IGV) | D25: : | E25: 638827.47
C26: Monto del contrato vigente (incl. IGV) | D26: : | E26: =+E25 -> 638827.47
C27: Adelanto directo otorgado | D27: : | E27: NO SE OTORGÓ ADELANTO
C28: Fecha efectiva del adelanto directo | D28: : | E28: -
C29: Adelanto de materiales otorgado | D29: : | E29: NO SE OTORGÓ ADELANTO
C30: Fecha efectiva del adelanto de materiales | D30: : | E30: -
C31: Plazo de ejecución contractual | D31: : | E31: SESENTA (60) DÍAS CALENDARIOS
C32: Residente de obra | D32: : | E32: ING. RAMIREZ BLANCO GABRIEL AUGUSTO HERMOGENES
C33: C. DE LA SUPERVISIÓN
C34: Contratista | D34: : | E34: PROYECTA PCL S.A.C
C35: Ruc N° | D35: : | E35: 20607943355
C36: Representante legal | D36: : | E36: SR. JOSÉ EDUARDO NIEVES CUADROS (DNI N°47768125)
C37: Domicilio legal | D37: : | E37: JR. BOLÍVAR HUÁNUCO - HUÁNUCO - HUÁNUCO
C38: Proceso de selección | D38: : | E38: CONTRATO MENOR
C39: Fecha de cuantía de contratación | D39: : | E39: 46195
C40: Contrato | D40: : | E40: CONTRATO DE CONSULTORÍA DE OBRA N°010-2026-MDPM/GM
C41: Fecha de firma del contrato | D41: : | E41: 46205
...

Sheet PRESUPUESTO
B1: PRESUPUESTO DE OBRA
B2: =+FT!E20 -> CONTRATO DE EJECUCIÓN DE OBRA N°004-2026-MDPM/GM
B3: Obra: | C3: =+FT!E5 -> "MEJORAMIENTO Y AMPLIACIÓN DE LOS SERVICIOS DE TRANSITABILIDAD VEHICULAR Y PEATONAL DEL JR LOS PINOS Y JR LOS CEDROS EN CAYHUAYNA Y CAYHUAYNA DEL DISTRITO DE PILLCO MARCA - PROVINCIA DE HUÁNUCO - DEPARTAMENTO DE HUÁNUCO" con CUI N°2536252
B4: Entidad: | C4: =+FT!$E$4 -> MUNICIPALIDAD DISTRITAL DE PILLCO MARCA
B5: Ejecutor: | C5: =+FT!$E$15 -> CONSORCIO EJECUTOR LOS PINOS
B6: Supervisor: | C6: =+FT!$E$34 -> PROYECTA PCL S.A.C
B7: Residente: | C7: =+FT!$E$32 -> ING. RAMIREZ BLANCO GABRIEL AUGUSTO HERMOGENES
B8: Ing. Supervisor: | C8: =+FT!$E$46 -> ING. CESAR RICARDO ZELADA RODRIGUEZ (CIP N° 98469)
B10: ITEM | C10: DESCRIPCION | D10: PRESUPUESTO DE OBRA
D11: UND | E11: METRADO | F11: P.UND | G11: TOTAL
B12: 01 | C12: CREACION DE PISTAS Y VEREDAS JR LOS CEDROS
B13: 01.01 | C13: OBRAS PROVISIONALES Y TRABAJOS PRELIMINARES
B14: 01.01.01 | C14: OBRAS PROVISIONALES
B15: 01.01.01.01 | C15: ALQUILER DE ALAMACEN, OFICINA Y CASETA DE GUARDIANIA | D15: mes | E15: 2 | F15: 2400 | G15: =ROUND(E15*F15,2) -> 4800
B16: 01.01.01.02 | C16: CARTEL DE IDENTIFICACION DE LA OBRA DE 3.60 x 4.80 m (SOPORTE DE MADERA) | D16: und | E16: 1 | F16: 1205.49 | G16: =ROUND(E16*F16,2) -> 1205.49
B17: 01.01.01.03 | C17: ALQUILER DE BAÑOS PORTATILES Y LAVADERO | D17: mes | E17: 2 | F17: 850 | G17: =ROUND(E17*F17,2) -> 1700
B18: 01.01.02 | C18: TRABAJOS PRELIMINARES | G18: =ROUND(E18*F18,2) -> 0
B19: 01.01.02.01 | C19: LIMPIEZA DE TERRENO MANUAL | D19: m2 | E19: 1932.21 | F19: 1.06 | G19: =ROUND(E19*F19,2) -> 2048.14
B20: 01.01.02.02 | C20: TRAZO Y REPLANTEO EN TERRENO NORMAL | D20: m2 | E20: 1932.21 | F20: 4.32 | G20: =ROUND(E20*F20,2) -> 8347.15
B21: 01.01.02.03 | C21: MOVILIZACION Y DESMOVILIZACIÓN DE MAQUINARIA Y EQUIPO | D21: GLB | E21: 1 | F21: 2500 | G21: =ROUND(E21*F21,2) -> 2500
B22: 01.01.03 | C22: DEMOLICIONES | G22: =ROUND(E22*F22,2) -> 0
B23: 01.01.03.01 | C23: DEMOLICION DE VEREDAS EXISTENTES DE 0.10M | D23: m2 | E23: 135.5 | F23: 21.33 | G23: =ROUND(E23*F23,2) -> 2890.22
B24: 01.01.03.02 | C24: ELIMINACION DE MATERIAL EXCEDENTE C/VOLQUETE DE 15M3 (D=10 KM) | D24: m3 | E24: 20.33 | F24: 18.98 | G24: =ROUND(E24*F24,2) -> 385.86
B25: 01.01.04 | C25: PLAN DE DESVIO VEHICULAR
B26: 01.01.04.01 | C26: TRANQUERAS DE MADERA 2.40 x 1.20 | D26: und | E26: 2 | F26: 221.35 | G26: =ROUND(E26*F26,2) -> 442.7
B27: 01.01.04.02 | C27: SEÑALIZACION DE DESVIO DE TRANSITO EN PERIODO DE CONSTRUCCION | D27: GLB | E27: 1 | F27: 221.16 | G27: =ROUND(E27*F27,2) -> 221.16
B28: 01.02 | C28: PAVIMENTO RIGIDO | G28: =ROUND(E28*F28,2) -> 0
B29: 01.02.01 | C29: MOVIMIENTO DE TIERRAS HASTA EL NIVEL DE SUB - RASANTE
B30: 01.02.01.01 | C30: CORTE EN TERRENO NORMAL CON MAQUINARIA | D30: m3 | E30: 590.54 | F30: 10.47 | G30: =ROUND(E30*F30,2) -> 6182.95
B31: 01.02.01.02 | C31: RELLENO COMPACTACION CON MATERIAL PROPIO SELECCIONADO | D31: m3 | E31: 51.64 | F31: 19.04 | G31: =ROUND(E31*F31,2) -> 983.23
B32: 01.02.01.03 | C32: ELIMINACION DE MATERIAL EXCEDENTE C/VOLQUETE DE 15M3 (D=10KM) | D32: m3 | E32: 738.18 | F32: 18.98 | G32: =ROUND(E32*F32,2) -> 14010.66
B33: 01.02.02 | C33: BASE | G33: =ROUND(E33*F33,2) -> 0
B34: 01.02.02.01 | C34: CONFORMACION DE BASE MATERIAL MEZCLADO E=0.20m | D34: m2 | E34: 910.14 | F34: 31.15 | G34: =ROUND(E34*F34,2) -> 28350.86
B35: 01.02.03 | C35: SUB RASANTE | G35: =ROUND(E35*F35,2) -> 0
B36: 01.02.03.01 | C36: PERFILADO, RIEGO Y COMPACTACIÓN DE SUBRASANTE | D36: m2 | E36: 910.14 | F36: 5.54 | G36: =ROUND(E36*F36,2) -> 5042.18
B37: 01.02.04 | C37: OBRAS DE CONCRETO | G37: =ROUND(E37*F37,2) -> 0
B38: 01.02.04.01 | C38: ENCOFRADO Y DESENCOFRADO EN PAVIMENTOS | D38: m2 | E38: 127.29 | F38: 63.41 | G38: =ROUND(E38*F38,2) -> 8071.46
B39: 01.02.04.02 | C39: CONCRETO F'C =210 KG/CM2 EN VIA E=15CM | D39: m2 | E39: 910.14 | F39: 119.99 | G39: =ROUND(E39*F39,2) -> 109207.7
B40: 01.02.04.03 | C40: CURADO DE CONCRETO | D40: m2 | E40: 910.14 | F40: 2.92 | G40: =ROUND(E40*F40,2) -> 2657.61
B41: 01.02.04.04 | C41: ACERO FY = 4200Kg/cm2 EN JUNTAS DE DILATACION LONGITUDINAL Ø 3/8" | D41: kg | E41: 80.64 | F41: 12.14 | G41: =ROUND(E41*F41,2) -> 978.97
...

Sheet CALEN. PROG.
B1: CALENDARIO DE AVANCE DE OBRA VALORIZADO PROGRAMADO ADECUADO AL INICIO DE LA OBRA
B2: Obra: | C2: =+FT!$E$5 -> "MEJORAMIENTO Y AMPLIACIÓN DE LOS SERVICIOS DE TRANSITABILIDAD VEHICULAR Y PEATONAL DEL JR LOS PINOS Y JR LOS CEDROS EN CAYHUAYNA Y CAYHUAYNA DEL DISTRITO DE PILLCO MARCA - PROVINCIA DE HUÁNUCO - DEPARTAMENTO DE HUÁNUCO" con CUI N°2536252
B3: Entidad: | C3: =+FT!$E$4 -> MUNICIPALIDAD DISTRITAL DE PILLCO MARCA
B4: Ejecutor: | C4: =+FT!$E$15 -> CONSORCIO EJECUTOR LOS PINOS
B5: Supervisor: | C5: =+FT!$E$34 -> PROYECTA PCL S.A.C | D5: VALOR REFERENCIAL (CON IGV) | G5: =+FT!$E$24 -> 638827.47
B6: Residente: | C6: =+FT!$E$32 -> ING. RAMIREZ BLANCO GABRIEL AUGUSTO HERMOGENES | D6: MONTO DEL CONTRATO (INCL. IGV): | G6: =+FT!$E$25 -> 638827.47
B7: Ing. Supervisor: | C7: =+FT!$E$46 -> ING. CESAR RICARDO ZELADA RODRIGUEZ (CIP N° 98469) | D7: PLAZO DE EJECUCIÓN: | G7: =+FT!$E$31 -> SESENTA (60) DÍAS CALENDARIOS
B9: ITEM | C9: DESCRIPCION | D9: PRESUPUESTO DE OBRA | I9: 46174 | L9: 46204 | O9: 46235
I10: 46193 | J10: 46203 | L10: 46204 | M10: 46234 | O10: 46235 | P10: 46253
D11: UND | E11: METRADO | F11: P.UND | G11: TOTAL | I11: PORCEN. (%) | J11: COSTO (S/) | L11: PORCEN. (%) | M11: COSTO (S/) | O11: PORCEN. (%) | P11: COSTO (S/)
B12: 01 | C12: CREACION DE PISTAS Y VEREDAS JR LOS CEDROS
B13: 01.01 | C13: OBRAS PROVISIONALES Y TRABAJOS PRELIMINARES
B14: 01.01.01 | C14: OBRAS PROVISIONALES
B15: 01.01.01.01 | C15: ALQUILER DE ALAMACEN, OFICINA Y CASETA DE GUARDIANIA | D15: mes | E15: 2 | F15: 2400 | G15: =ROUND(E15*F15,2) -> 4800 | I15: =ROUND(J15/$G15,4) -> 0.3333 | J15: 1600 | L15: =ROUND(M15/$G15,4) -> 0.3333 | M15: 1600 | O15: =ROUND(P15/$G15,4) -> 0.3333 | P15: 1600
B16: 01.01.01.02 | C16: CARTEL DE IDENTIFICACION DE LA OBRA DE 3.60 x 4.80 m (SOPORTE DE MADERA) | D16: und | E16: 1 | F16: 1205.49 | G16: =ROUND(E16*F16,2) -> 1205.49 | I16: =ROUND(J16/$G16,4) -> 1 | J16: 1205.49 | L16: =ROUND(M16/$G16,4) -> 0 | O16: =ROUND(P16/$G16,4) -> 0
B17: 01.01.01.03 | C17: ALQUILER DE BAÑOS PORTATILES Y LAVADERO | D17: mes | E17: 2 | F17: 850 | G17: =ROUND(E17*F17,2) -> 1700 | I17: =ROUND(J17/$G17,4) -> 0.1833 | J17: 311.66667 | L17: =ROUND(M17/$G17,4) -> 0.5167 | M17: 878.33333 | O17: =ROUND(P17/$G17,4) -> 0.3 | P17: 510
B18: 01.01.02 | C18: TRABAJOS PRELIMINARES | G18: =ROUND(E18*F18,2) -> 0
B19: 01.01.02.01 | C19: LIMPIEZA DE TERRENO MANUAL | D19: m2 | E19: 1932.21 | F19: 1.06 | G19: =ROUND(E19*F19,2) -> 2048.14 | I19: =ROUND(J19/$G19,4) -> 1 | J19: 2048.14 | L19: =ROUND(M19/$G19,4) -> 0 | O19: =ROUND(P19/$G19,4) -> 0
B20: 01.01.02.02 | C20: TRAZO Y REPLANTEO EN TERRENO NORMAL | D20: m2 | E20: 1932.21 | F20: 4.32 | G20: =ROUND(E20*F20,2) -> 8347.15 | I20: =ROUND(J20/$G20,4) -> 0.1046 | J20: 873.44 | L20: =ROUND(M20/$G20,4) -> 0.4539 | M20: 3789.15 | O20: =ROUND(P20/$G20,4) -> 0.4414 | P20: 3684.56
B21: 01.01.02.03 | C21: MOVILIZACION Y DESMOVILIZACION DE MAQUINARIA Y EQUIPO | D21: GLB | E21: 1 | F21: 2500 | G21: =ROUND(E21*F21,2) -> 2500 | I21: =ROUND(J21/$G21,4) -> 1 | J21: 2500 | L21: =ROUND(M21/$G21,4) -> 0 | O21: =ROUND(P21/$G21,4) -> 0
B22: 01.01.03 | C22: DEMOLICIONES | G22: =ROUND(E22*F22,2) -> 0
B23: 01.01.03.01 | C23: DEMOLICION DE VEREDAS EXISTENTES DE 0.10M | D23: m2 | E23: 135.5 | F23: 21.33 | G23: =ROUND(E23*F23,2) -> 2890.22 | I23: =ROUND(J23/$G23,4) -> 1 | J23: 2890.22 | L23: =ROUND(M23/$G23,4) -> 0 | O23: =ROUND(P23/$G23,4) -> 0
B24: 01.01.03.02 | C24: ELIMINACION DE MATERIAL EXCEDENTE C/VOLQUETE DE 15M3 (D=10 KM) | D24: m3 | E24: 20.33 | F24: 18.98 | G24: =ROUND(E24*F24,2) -> 385.86 | I24: =ROUND(J24/$G24,4) -> 1 | J24: 385.86 | L24: =ROUND(M24/$G24,4) -> 0 | O24: =ROUND(P24/$G24,4) -> 0
B25: 01.01.04 | C25: PLAN DE DESVIO VEHICULAR
B26: 01.01.04.01 | C26: TRANQUERAS DE MADERA 2.40 x 1.20 | D26: und | E26: 2 | F26: 221.35 | G26: =ROUND(E26*F26,2) -> 442.7 | I26: =ROUND(J26/$G26,4) -> 1 | J26: 442.7 | L26: =ROUND(M26/$G26,4) -> 0 | O26: =ROUND(P26/$G26,4) -> 0
B27: 01.01.04.02 | C27: SEÑALIZACION DE DESVIO DE TRANSITO EN PERIODO DE CONSTRUCCION | D27: GLB | E27: 1 | F27: 221.16 | G27: =ROUND(E27*F27,2) -> 221.16 | I27: =ROUND(J27/$G27,4) -> 1 | J27: 221.16 | L27: =ROUND(M27/$G27,4) -> 0 | O27: =ROUND(P27/$G27,4) -> 0
B28: 01.02 | C28: PAVIMENTO RIGIDO | G28: =ROUND(E28*F28,2) -> 0
B29: 01.02.01 | C29: MOVIMIENTO DE TIERRAS HASTA EL NIVEL DE SUB - RASANTE
B30: 01.02.01.01 | C30: CORTE EN TERRENO NORMAL CON MAQUINARIA | D30: m3 | E30: 590.54 | F30: 10.47 | G30: =ROUND(E30*F30,2) -> 6182.95 | I30: =ROUND(J30/$G30,4) -> 1 | J30: 6182.95 | L30: =ROUND(M30/$G30,4) -> 0 | O30: =ROUND(P30/$G30,4) -> 0
B31: 01.02.01.02 | C31: RELLENO COMPACTACION CON MATERIAL PROPIO SELECCIONADO | D31: m3 | E31: 51.64 | F31: 19.04 | G31: =ROUND(E31*F31,2) -> 983.23 | I31: =ROUND(J31/$G31,4) -> 1 | J31: 983.23 | L31: =ROUND(M31/$G31,4) -> 0 | O31: =ROUND(P31/$G31,4) -> 0
B32: 01.02.01.03 | C32: ELIMINACION DE MATERIAL EXCEDENTE C/VOLQUETE DE 15M3 (D=10KM) | D32: m3 | E32: 738.18 | F32: 18.98 | G32: =ROUND(E32*F32,2) -> 14010.66 | I32: =ROUND(J32/$G32,4) -> 0 | L32: =ROUND(M32/$G32,4) -> 1 | M32: 14010.66 | O32: =ROUND(P32/$G32,4) -> 0
B33: 01.02.02 | C33: BASE | G33: =ROUND(E33*F33,2) -> 0
B34: 01.02.02.01 | C34: CONFORMACION DE BASE MATERIAL MEZCLADO E=0.20m | D34: m2 | E34: 910.14 | F34: 31.15 | G34: =ROUND(E34*F34,2) -> 28350.86 | I34: =ROUND(J34/$G34,4) -> 1 | J34: 28350.86 | L34: =ROUND(M34/$G34,4) -> 0 | O34: =ROUND(P34/$G34,4) -> 0
B35: 01.02.03 | C35: SUB RASANTE | G35: =ROUND(E35*F35,2) -> 0
B36: 01.02.03.01 | C36: PERFILADO, RIEGO Y COMPACTACIÓN DE SUBRASANTE | D36: m2 | E36: 910.14 | F36: 5.54 | G36: =ROUND(E36*F36,2) -> 5042.18 | I36: =ROUND(J36/$G36,4) -> 1 | J36: 5042.18 | L36: =ROUND(M36/$G36,4) -> 0 | O36: =ROUND(P36/$G36,4) -> 0
B37: 01.02.04 | C37: OBRAS DE CONCRETO | G37: =ROUND(E37*F37,2) -> 0
B38: 01.02.04.01 | C38: ENCOFRADO Y DESENCOFRADO EN PAVIMENTOS | D38: m2 | E38: 127.29 | F38: 63.41 | G38: =ROUND(E38*F38,2) -> 8071.46 | I38: =ROUND(J38/$G38,4) -> 1 | J38: 8071.46 | L38: =ROUND(M38/$G38,4) -> 0 | O38: =ROUND(P38/$G38,4) -> 0
B39: 01.02.04.02 | C39: CONCRETO F'C =210 KG/CM2 EN VIA E=15CM | D39: m2 | E39: 910.14 | F39: 119.99 | G39: =ROUND(E39*F39,2) -> 109207.7 | I39: =ROUND(J39/$G39,4) -> 0.0787 | J39: 8593.32 | L39: =ROUND(M39/$G39,4) -> 0.9213 | M39: 100614.38 | O39: =ROUND(P39/$G39,4) -> 0
B40: 01.02.04.03 | C40: CURADO DE CONCRETO | D40: m2 | E40: 910.14 | F40: 2.92 | G40: =ROUND(E40*F40,2) -> 2657.61 | I40: =ROUND(J40/$G40,4) -> 0 | L40: =ROUND(M40/$G40,4) -> 1 | M40: 2657.61 | O40: =ROUND(P40/$G40,4) -> 0
B41: 01.02.04.04 | C41: ACERO FY = 4200Kg/cm2 EN JUNTAS DE DILATACION LONGITUDINAL Ø 3/8" | D41: kg | E41: 80.64 | F41: 12.14 | G41: =ROUND(E41*F41,2) -> 978.97 | I41: =ROUND(J41/$G41,4) -> 1 | J41: 978.97 | L41: =ROUND(M41/$G41,4) -> 0 | O41: =ROUND(P41/$G41,4) -> 0
...

Sheet METRADOS
B1: RESUMEN DE METRADOS EJECUTADOS EN EL PRESENTE MES
B2: Obra: | C2: =+FT!$E$5 -> "MEJORAMIENTO Y AMPLIACIÓN DE LOS SERVICIOS DE TRANSITABILIDAD VEHICULAR Y PEATONAL DEL JR LOS PINOS Y JR LOS CEDROS EN CAYHUAYNA Y CAYHUAYNA DEL DISTRITO DE PILLCO MARCA - PROVINCIA DE HUÁNUCO - DEPARTAMENTO DE HUÁNUCO" con CUI N°2536252
B3: Entidad: | C3: =+FT!$E$4 -> MUNICIPALIDAD DISTRITAL DE PILLCO MARCA
B4: Ejecutor: | C4: =+FT!$E$15 -> CONSORCIO EJECUTOR LOS PINOS
B5: Supervisor: | C5: =+FT!$E$34 -> PROYECTA PCL S.A.C | D5: VALOR REFERENCIAL (CON IGV) | G5: =+FT!$E$24 -> 638827.47
B6: Residente: | C6: =+FT!$E$32 -> ING. RAMIREZ BLANCO GABRIEL AUGUSTO HERMOGENES | D6: MONTO DEL CONTRATO (INCL. IGV): | G6: =+FT!$E$25 -> 638827.47
B7: Ing. Supervisor: | C7: =+FT!$E$46 -> ING. CESAR RICARDO ZELADA RODRIGUEZ (CIP N° 98469) | D7: PLAZO DE EJECUCIÓN: | G7: =+FT!$E$31 -> SESENTA (60) DÍAS CALENDARIOS
B9: ITEM | C9: DESCRIPCION | D9: METRADO CONTRATADO | G9: 46174 | I9: 46204 | K9: 46143 | M9: METRADO ACUMULADO | O9: SALDO POR METRAR
D10: UND | E10: METRADO | G10: METRADO | I10: METRADO | K10: METRADO
B11: 01 | C11: CREACION DE PISTAS Y VEREDAS JR LOS CEDROS
B12: 01.01 | C12: OBRAS PROVISIONALES Y TRABAJOS PRELIMINARES | M12: =+G12+I12+K12 -> 0 | O12: =+E12-M12 -> 0
B13: 01.01.01 | C13: OBRAS PROVISIONALES
B14: 01.01.01.01 | C14: ALQUILER DE ALAMACEN, OFICINA Y CASETA DE GUARDIANIA | D14: mes | E14: 2 | G14: 1 | I14: 0.48 | M14: =+G14+I14+K14 -> 1.48 | O14: =+E14-M14 -> 0.52
B15: 01.01.01.02 | C15: CARTEL DE IDENTIFICACION DE LA OBRA DE 3.60 x 4.80 m (SOPORTE DE MADERA) | D15: und | E15: 1 | G15: 1 | M15: =+G15+I15+K15 -> 1 | O15: =+E15-M15 -> 0
B16: 01.01.01.03 | C16: ALQUILER DE BAÑOS PORTATILES Y LAVADERO | D16: mes | E16: 2 | G16: 1 | I16: 0.48 | M16: =+G16+I16+K16 -> 1.48 | O16: =+E16-M16 -> 0.52
B17: 01.01.02 | C17: TRABAJOS PRELIMINARES
B18: 01.01.02.01 | C18: LIMPIEZA DE TERRENO MANUAL | D18: m2 | E18: 1932.21 | G18: 1932.21 | M18: =+G18+I18+K18 -> 1932.21 | O18: =+E18-M18 -> 0
B19: 01.01.02.02 | C19: TRAZO Y REPLANTEO EN TERRENO NORMAL | D19: m2 | E19: 1932.21 | G19: 1932.21 | M19: =+G19+I19+K19 -> 1932.21 | O19: =+E19-M19 -> 0
B20: 01.01.02.03 | C20: MOVILIZACION Y DESMOVILIZACIÓN DE MAQUINARIA Y EQUIPO | D20: GLB | E20: 1 | G20: 1 | M20: =+G20+I20+K20 -> 1 | O20: =+E20-M20 -> 0
B21: 01.01.03 | C21: DEMOLICIONES
B22: 01.01.03.01 | C22: DEMOLICION DE VEREDAS EXISTENTES DE 0.10M | D22: m2 | E22: 135.5 | G22: 135.5 | M22: =+G22+I22+K22 -> 135.5 | O22: =+E22-M22 -> 0
B23: 01.01.03.02 | C23: ELIMINACION DE MATERIAL EXCEDENTE C/VOLQUETE DE 15M3 (D=10 KM) | D23: m3 | E23: 20.33 | G23: 20.33 | M23: =+G23+I23+K23 -> 20.33 | O23: =+E23-M23 -> 0
B24: 01.01.04 | C24: PLAN DE DESVIO VEHICULAR
B25: 01.01.04.01 | C25: TRANQUERAS DE MADERA 2.40 x 1.20 | D25: und | E25: 2 | G25: 2 | M25: =+G25+I25+K25 -> 2 | O25: =+E25-M25 -> 0
B26: 01.01.04.02 | C26: SEÑALIZACION DE DESVIO DE TRANSITO EN PERIODO DE CONSTRUCCION | D26: GLB | E26: 1 | G26: 1 | M26: =+G26+I26+K26 -> 1 | O26: =+E26-M26 -> 0
B27: 01.02 | C27: PAVIMENTO RIGIDO
B28: 01.02.01 | C28: MOVIMIENTO DE TIERRAS HASTA EL NIVEL DE SUB - RASANTE
B29: 01.02.01.01 | C29: CORTE EN TERRENO NORMAL CON MAQUINARIA | D29: m3 | E29: 590.54 | G29: 590.54 | M29: =+G29+I29+K29 -> 590.54 | O29: =+E29-M29 -> 0
B30: 01.02.01.02 | C30: RELLENO COMPACTACION CON MATERIAL PROPIO SELECCIONADO | D30: m3 | E30: 51.64 | G30: 51.64 | M30: =+G30+I30+K30 -> 51.64 | O30: =+E30-M30 -> 0
B31: 01.02.01.03 | C31: ELIMINACION DE MATERIAL EXCEDENTE C/VOLQUETE DE 15M3 (D=10KM) | D31: m3 | E31: 738.18 | G31: 738.18 | M31: =+G31+I31+K31 -> 738.18 | O31: =+E31-M31 -> 0
B32: 01.02.02 | C32: BASE
B33: 01.02.02.01 | C33: CONFORMACION DE BASE MATERIAL MEZCLADO E=0.20m | D33: m2 | E33: 910.14 | G33: 910.14 | M33: =+G33+I33+K33 -> 910.14 | O33: =+E33-M33 -> 0
B34: 01.02.03 | C34: SUB RASANTE
B35: 01.02.03.01 | C35: PERFILADO, RIEGO Y COMPACTACIÓN DE SUBRASANTE | D35: m2 | E35: 910.14 | G35: 910.14 | M35: =+G35+I35+K35 -> 910.14 | O35: =+E35-M35 -> 0
B36: 01.02.04 | C36: OBRAS DE CONCRETO
B37: 01.02.04.01 | C37: ENCOFRADO Y DESENCOFRADO EN PAVIMENTOS | D37: m2 | E37: 127.29 | G37: 127.29 | M37: =+G37+I37+K37 -> 127.29 | O37: =+E37-M37 -> 0
B38: 01.02.04.02 | C38: CONCRETO F'C =210 KG/CM2 EN VIA E=15CM | D38: m2 | E38: 910.14 | G38: 910.14 | M38: =+G38+I38+K38 -> 910.14 | O38: =+E38-M38 -> 0
B39: 01.02.04.03 | C39: CURADO DE CONCRETO | D39: m2 | E39: 910.14 | G39: 910.14 | M39: =+G39+I39+K39 -> 910.14 | O39: =+E39-M39 -> 0
B40: 01.02.04.04 | C40: ACERO FY = 4200Kg/cm2 EN JUNTAS DE DILATACION LONGITUDINAL Ø 3/8" | D40: kg | E40: 80.64 | G40: 80.64 | M40: =+G40+I40+K40 -> 80.64 | O40: =+E40-M40 -> 0
B41: 01.02.04.05 | C41: ACERO FY = 2400Kg/cm2 GRADO 60 EN JUNTAS DE DILATACION TRANSVERSAL Ø 3/4" | D41: kg | E41: 176.4 | G41: 176.4 | M41: =+G41+I41+K41 -> 176.4 | O41: =+E41-M41 -> 0
...

Sheet CALEN. VALO.
B1: CALENDARIO DE AVANCE DE OBRA VALORIZADO EJECUTADO
B2: Obra: | C2: =+FT!$E$5 -> "MEJORAMIENTO Y AMPLIACIÓN DE LOS SERVICIOS DE TRANSITABILIDAD VEHICULAR Y PEATONAL DEL JR LOS PINOS Y JR LOS CEDROS EN CAYHUAYNA Y CAYHUAYNA DEL DISTRITO DE PILLCO MARCA - PROVINCIA DE HUÁNUCO - DEPARTAMENTO DE HUÁNUCO" con CUI N°2536252
B3: Entidad: | C3: =+FT!$E$4 -> MUNICIPALIDAD DISTRITAL DE PILLCO MARCA
B4: Ejecutor: | C4: =+FT!$E$15 -> CONSORCIO EJECUTOR LOS PINOS
B5: Supervisor: | C5: =+FT!$E$34 -> PROYECTA PCL S.A.C | D5: VALOR REFERENCIAL (CON IGV) | G5: =+FT!$E$24 -> 638827.47
B6: Residente: | C6: =+FT!$E$32 -> ING. RAMIREZ BLANCO GABRIEL AUGUSTO HERMOGENES | D6: MONTO DEL CONTRATO (INCL. IGV): | G6: =+FT!$E$25 -> 638827.47
B7: Ing. Supervisor: | C7: =+FT!$E$46 -> ING. CESAR RICARDO ZELADA RODRIGUEZ (CIP N° 98469) | D7: PLAZO DE EJECUCIÓN: | G7: =+FT!$E$31 -> SESENTA (60) DÍAS CALENDARIOS
B9: ITEM | C9: DESCRIPCION | D9: PRESUPUESTO DE OBRA | I9: 46174 | L9: 46204 | O9: 46235
I10: 46193 | J10: 46203 | L10: 46204 | M10: 46234 | O10: 46235 | P10: 46253
D11: UND | E11: METRADO | F11: P.UND | G11: TOTAL | I11: PORCEN. (%) | J11: COSTO (S/) | L11: PORCEN. (%) | M11: COSTO (S/) | O11: PORCEN. (%) | P11: COSTO (S/)
B12: 01 | C12: CREACION DE PISTAS Y VEREDAS JR LOS CEDROS
B13: 01.01 | C13: OBRAS PROVISIONALES Y TRABAJOS PRELIMINARES
B14: 01.01.01 | C14: OBRAS PROVISIONALES
B15: 01.01.01.01 | C15: ALQUILER DE ALAMACEN, OFICINA Y CASETA DE GUARDIANIA | D15: mes | E15: 2 | F15: 2400 | G15: =ROUND(E15*F15,2) -> 4800 | I15: =ROUND(J15/$G15,4) -> 0.5 | J15: 2400 | L15: =ROUND(M15/$G15,4) -> 0.24 | M15: 1152 | O15: =ROUND(P15/$G15,4) -> 0
B16: 01.01.01.02 | C16: CARTEL DE IDENTIFICACION DE LA OBRA DE 3.60 x 4.80 m (SOPORTE DE MADERA) | D16: und | E16: 1 | F16: 1205.49 | G16: =ROUND(E16*F16,2) -> 1205.49 | I16: =ROUND(J16/$G16,4) -> 1 | J16: 1205.49 | L16: =ROUND(M16/$G16,4) -> 0 | M16: 0 | O16: =ROUND(P16/$G16,4) -> 0
B17: 01.01.01.03 | C17: ALQUILER DE BAÑOS PORTATILES Y LAVADERO | D17: mes | E17: 2 | F17: 850 | G17: =ROUND(E17*F17,2) -> 1700 | I17: =ROUND(J17/$G17,4) -> 0.5 | J17: 850 | L17: =ROUND(M17/$G17,4) -> 0.24 | M17: 408 | O17: =ROUND(P17/$G17,4) -> 0
B18: 01.01.02 | C18: TRABAJOS PRELIMINARES | G18: =ROUND(E18*F18,2) -> 0
B19: 01.01.02.01 | C19: LIMPIEZA DE TERRENO MANUAL | D19: m2 | E19: 1932.21 | F19: 1.06 | G19: =ROUND(E19*F19,2) -> 2048.14 | I19: =ROUND(J19/$G19,4) -> 1 | J19: 2048.14 | L19: =ROUND(M19/$G19,4) -> 0 | M19: 0 | O19: =ROUND(P19/$G19,4) -> 0
B20: 01.01.02.02 | C20: TRAZO Y REPLANTEO EN TERRENO NORMAL | D20: m2 | E20: 1932.21 | F20: 4.32 | G20: =ROUND(E20*F20,2) -> 8347.15 | I20: =ROUND(J20/$G20,4) -> 1 | J20: 8347.15 | L20: =ROUND(M20/$G20,4) -> 0 | M20: 0 | O20: =ROUND(P20/$G20,4) -> 0
B21: 01.01.02.03 | C21: MOVILIZACION Y DESMOVILIZACION DE MAQUINARIA Y EQUIPO | D21: GLB | E21: 1 | F21: 2500 | G21: =ROUND(E21*F21,2) -> 2500 | I21: =ROUND(J21/$G21,4) -> 1 | J21: 2500 | L21: =ROUND(M21/$G21,4) -> 0 | M21: 0 | O21: =ROUND(P21/$G21,4) -> 0
B22: 01.01.03 | C22: DEMOLICIONES | G22: =ROUND(E22*F22,2) -> 0
B23: 01.01.03.01 | C23: DEMOLICION DE VEREDAS EXISTENTES DE 0.10M | D23: m2 | E23: 135.5 | F23: 21.33 | G23: =ROUND(E23*F23,2) -> 2890.22 | I23: =ROUND(J23/$G23,4) -> 1 | J23: 2890.22 | L23: =ROUND(M23/$G23,4) -> 0 | M23: 0 | O23: =ROUND(P23/$G23,4) -> 0
B24: 01.01.03.02 | C24: ELIMINACION DE MATERIAL EXCEDENTE C/VOLQUETE DE 15M3 (D=10 KM) | D24: m3 | E24: 20.33 | F24: 18.98 | G24: =ROUND(E24*F24,2) -> 385.86 | I24: =ROUND(J24/$G24,4) -> 1 | J24: 385.86 | L24: =ROUND(M24/$G24,4) -> 0 | M24: 0 | O24: =ROUND(P24/$G24,4) -> 0
B25: 01.01.04 | C25: PLAN DE DESVIO VEHICULAR
B26: 01.01.04.01 | C26: TRANQUERAS DE MADERA 2.40 x 1.20 | D26: und | E26: 2 | F26: 221.35 | G26: =ROUND(E26*F26,2) -> 442.7 | I26: =ROUND(J26/$G26,4) -> 1 | J26: 442.7 | L26: =ROUND(M26/$G26,4) -> 0 | M26: 0 | O26: =ROUND(P26/$G26,4) -> 0
B27: 01.01.04.02 | C27: SEÑALIZACION DE DESVIO DE TRANSITO EN PERIODO DE CONSTRUCCION | D27: GLB | E27: 1 | F27: 221.16 | G27: =ROUND(E27*F27,2) -> 221.16 | I27: =ROUND(J27/$G27,4) -> 1 | J27: 221.16 | L27: =ROUND(M27/$G27,4) -> 0 | M27: 0 | O27: =ROUND(P27/$G27,4) -> 0
B28: 01.02 | C28: PAVIMENTO RIGIDO | G28: =ROUND(E28*F28,2) -> 0
B29: 01.02.01 | C29: MOVIMIENTO DE TIERRAS HASTA EL NIVEL DE SUB - RASANTE
B30: 01.02.01.01 | C30: CORTE EN TERRENO NORMAL CON MAQUINARIA | D30: m3 | E30: 590.54 | F30: 10.47 | G30: =ROUND(E30*F30,2) -> 6182.95 | I30: =ROUND(J30/$G30,4) -> 1 | J30: 6182.95 | L30: =ROUND(M30/$G30,4) -> 0 | M30: 0 | O30: =ROUND(P30/$G30,4) -> 0
B31: 01.02.01.02 | C31: RELLENO COMPACTACION CON MATERIAL PROPIO SELECCIONADO | D31: m3 | E31: 51.64 | F31: 19.04 | G31: =ROUND(E31*F31,2) -> 983.23 | I31: =ROUND(J31/$G31,4) -> 1 | J31: 983.23 | L31: =ROUND(M31/$G31,4) -> 0 | M31: 0 | O31: =ROUND(P31/$G31,4) -> 0
B32: 01.02.01.03 | C32: ELIMINACION DE MATERIAL EXCEDENTE C/VOLQUETE DE 15M3 (D=10KM) | D32: m3 | E32: 738.18 | F32: 18.98 | G32: =ROUND(E32*F32,2) -> 14010.66 | I32: =ROUND(J32/$G32,4) -> 1 | J32: 14010.66 | L32: =ROUND(M32/$G32,4) -> 0 | M32: 0 | O32: =ROUND(P32/$G32,4) -> 0
B33: 01.02.02 | C33: BASE | G33: =ROUND(E33*F33,2) -> 0
B34: 01.02.02.01 | C34: CONFORMACION DE BASE MATERIAL MEZCLADO E=0.20m | D34: m2 | E34: 910.14 | F34: 31.15 | G34: =ROUND(E34*F34,2) -> 28350.86 | I34: =ROUND(J34/$G34,4) -> 1 | J34: 28350.86 | L34: =ROUND(M34/$G34,4) -> 0 | M34: 0 | O34: =ROUND(P34/$G34,4) -> 0
B35: 01.02.03 | C35: SUB RASANTE | G35: =ROUND(E35*F35,2) -> 0
B36: 01.02.03.01 | C36: PERFILADO, RIEGO Y COMPACTACIÓN DE SUBRASANTE | D36: m2 | E36: 910.14 | F36: 5.54 | G36: =ROUND(E36*F36,2) -> 5042.18 | I36: =ROUND(J36/$G36,4) -> 1 | J36: 5042.18 | L36: =ROUND(M36/$G36,4) -> 0 | M36: 0 | O36: =ROUND(P36/$G36,4) -> 0
B37: 01.02.04 | C37: OBRAS DE CONCRETO | G37: =ROUND(E37*F37,2) -> 0
B38: 01.02.04.01 | C38: ENCOFRADO Y DESENCOFRADO EN PAVIMENTOS | D38: m2 | E38: 127.29 | F38: 63.41 | G38: =ROUND(E38*F38,2) -> 8071.46 | I38: =ROUND(J38/$G38,4) -> 1 | J38: 8071.46 | L38: =ROUND(M38/$G38,4) -> 0 | M38: 0 | O38: =ROUND(P38/$G38,4) -> 0
B39: 01.02.04.02 | C39: CONCRETO F'C =210 KG/CM2 EN VIA E=15CM | D39: m2 | E39: 910.14 | F39: 119.99 | G39: =ROUND(E39*F39,2) -> 109207.7 | I39: =ROUND(J39/$G39,4) -> 1 | J39: 109207.7 | L39: =ROUND(M39/$G39,4) -> 0 | M39: 0 | O39: =ROUND(P39/$G39,4) -> 0
B40: 01.02.04.03 | C40: CURADO DE CONCRETO | D40: m2 | E40: 910.14 | F40: 2.92 | G40: =ROUND(E40*F40,2) -> 2657.61 | I40: =ROUND(J40/$G40,4) -> 1 | J40: 2657.61 | L40: =ROUND(M40/$G40,4) -> 0 | M40: 0 | O40: =ROUND(P40/$G40,4) -> 0
B41: 01.02.04.04 | C41: ACERO FY = 4200Kg/cm2 EN JUNTAS DE DILATACION LONGITUDINAL Ø 3/8" | D41: kg | E41: 80.64 | F41: 12.14 | G41: =ROUND(E41*F41,2) -> 978.97 | I41: =ROUND(J41/$G41,4) -> 1 | J41: 978.97 | L41: =ROUND(M41/$G41,4) -> 0 | M41: 0 | O41: =ROUND(P41/$G41,4) -> 0
...

Sheet VAL. MENSUAL
B1: VALORIZACIÓN N°02 DEL MES DE JULIO DE 2026
B2: =+FT!E20 -> CONTRATO DE EJECUCIÓN DE OBRA N°004-2026-MDPM/GM
B3: Obra: | C3: "MEJORAMIENTO Y AMPLIACION DE LOS SERVICIOS DE TRANSITABILIDAD VEHICULAR Y PEATONAL DEL JR LOS PINOS Y JR LOS CEDROS EN CAYHUAYNA Y CAYHUAYNA DEL DISTRITO DE PILLCO MARCA - PROVINCIA DE HUANUCO - DEPARTAMENTO DE HUANUCO" CON CUI N°2536252
B4: Entidad: | C4: MUNICIPALIDAD DISTRITAL DE PILLCO MARCA
B5: Ejecutor: | C5: =+FT!$E$15 -> CONSORCIO EJECUTOR LOS PINOS
B6: Supervisor: | C6: =+FT!$E$34 -> PROYECTA PCL S.A.C | D6: VALOR REFERENCIAL (CON IGV) | G6: 638827.47
B7: Residente: | C7: =+FT!$E$32 -> ING. RAMIREZ BLANCO GABRIEL AUGUSTO HERMOGENES | D7: MONTO DEL CONTRATO (INCL. IGV): | G7: 638827.47
B8: Ing. Supervisor: | C8: =+FT!$E$46 -> ING. CESAR RICARDO ZELADA RODRIGUEZ (CIP N° 98469) | D8: PLAZO DE EJECUCIÓN: | G8: SESENTA (60) DÍAS CALENDARIOS
B10: ITEM | C10: DESCRIPCION | D10: PRESUPUESTO DE OBRA | I10: ACUMULADO ANTERIOR | M10: ACTUAL | Q10: ACUMULADO ACTUAL | U10: SALDO
D11: UND | E11: METRADO | F11: P.UND | G11: TOTAL | I11: METRADO | J11: COSTO (S/) | K11: % | M11: METRADO | N11: COSTO (S/) | O11: % | Q11: METRADO | R11: COSTO (S/) | S11: % | U11: METRADO | V11: COSTO (S/) | W11: %
B12: 01 | C12: CREACION DE PISTAS Y VEREDAS JR LOS CEDROS
B13: 01.01 | C13: OBRAS PROVISIONALES Y TRABAJOS PRELIMINARES
B14: 01.01.01 | C14: OBRAS PROVISIONALES
B15: 01.01.01.01 | C15: ALQUILER DE ALAMACEN, OFICINA Y CASETA DE GUARDIANIA | D15: mes | E15: 2 | F15: 2400 | G15: =ROUND(E15*F15,2) -> 4800 | I15: 1 | J15: 2400 | K15: 0.5 | M15: 0.48 | N15: =ROUND(M15*$F15,2) -> 1152 | O15: =ROUND(N15/$G15,4) -> 0.24 | Q15: =+I15+M15 -> 1.48 | R15: =+J15+N15 -> 3552 | S15: =+K15+O15 -> 0.74 | U15: =+E15-Q15 -> 0.52 | V15: =+G15-R15 -> 1248 | W15: =1-S15 -> 0.26
B16: 01.01.01.02 | C16: CARTEL DE IDENTIFICACION DE LA OBRA DE 3.60 x 4.80 m (SOPORTE DE MADERA) | D16: und | E16: 1 | F16: 1205.49 | G16: =ROUND(E16*F16,2) -> 1205.49 | I16: 1 | J16: 1205.49 | K16: 1 | N16: =ROUND(M16*$F16,2) -> 0 | O16: =ROUND(N16/$G16,4) -> 0 | Q16: =+I16+M16 -> 1 | R16: =+J16+N16 -> 1205.49 | S16: =+K16+O16 -> 1 | U16: =+E16-Q16 -> 0 | V16: =+G16-R16 -> 0 | W16: =1-S16 -> 0
B17: 01.01.01.03 | C17: ALQUILER DE BAÑOS PORTATILES Y LAVADERO | D17: mes | E17: 2 | F17: 850 | G17: =ROUND(E17*F17,2) -> 1700 | I17: 1 | J17: 850 | K17: 0.5 | M17: 0.48 | N17: =ROUND(M17*$F17,2) -> 408 | O17: =ROUND(N17/$G17,4) -> 0.24 | Q17: =+I17+M17 -> 1.48 | R17: =+J17+N17 -> 1258 | S17: =+K17+O17 -> 0.74 | U17: =+E17-Q17 -> 0.52 | V17: =+G17-R17 -> 442 | W17: =1-S17 -> 0.26
B18: 01.01.02 | C18: TRABAJOS PRELIMINARES | G18: =ROUND(E18*F18,2) -> 0
B19: 01.01.02.01 | C19: LIMPIEZA DE TERRENO MANUAL | D19: m2 | E19: 1932.21 | F19: 1.06 | G19: =ROUND(E19*F19,2) -> 2048.14 | I19: 1932.21 | J19: 2048.14 | K19: 1 | N19: =ROUND(M19*$F19,2) -> 0 | O19: =ROUND(N19/$G19,4) -> 0 | Q19: =+I19+M19 -> 1932.21 | R19: =+J19+N19 -> 2048.14 | S19: =+K19+O19 -> 1 | U19: =+E19-Q19 -> 0 | V19: =+G19-R19 -> 0 | W19: =1-S19 -> 0
B20: 01.01.02.02 | C20: TRAZO Y REPLANTEO EN TERRENO NORMAL | D20: m2 | E20: 1932.21 | F20: 4.32 | G20: =ROUND(E20*F20,2) -> 8347.15 | I20: 1932.21 | J20: 8347.15 | K20: 1 | N20: =ROUND(M20*$F20,2) -> 0 | O20: =ROUND(N20/$G20,4) -> 0 | Q20: =+I20+M20 -> 1932.21 | R20: =+J20+N20 -> 8347.15 | S20: =+K20+O20 -> 1 | U20: =+E20-Q20 -> 0 | V20: =+G20-R20 -> 0 | W20: =1-S20 -> 0
B21: 01.01.02.03 | C21: MOVILIZACION Y DESMOVILIZACION DE MAQUINARIA Y EQUIPO | D21: GLB | E21: 1 | F21: 2500 | G21: =ROUND(E21*F21,2) -> 2500 | I21: 1 | J21: 2500 | K21: 1 | N21: =ROUND(M21*$F21,2) -> 0 | O21: =ROUND(N21/$G21,4) -> 0 | Q21: =+I21+M21 -> 1 | R21: =+J21+N21 -> 2500 | S21: =+K21+O21 -> 1 | U21: =+E21-Q21 -> 0 | V21: =+G21-R21 -> 0 | W21: =1-S21 -> 0
B22: 01.01.03 | C22: DEMOLICIONES | G22: =ROUND(E22*F22,2) -> 0
B23: 01.01.03.01 | C23: DEMOLICION DE VEREDAS EXISTENTES DE 0.10M | D23: m2 | E23: 135.5 | F23: 21.33 | G23: =ROUND(E23*F23,2) -> 2890.22 | I23: 135.5 | J23: 2890.22 | K23: 1 | N23: =ROUND(M23*$F23,2) -> 0 | O23: =ROUND(N23/$G23,4) -> 0 | Q23: =+I23+M23 -> 135.5 | R23: =+J23+N23 -> 2890.22 | S23: =+K23+O23 -> 1 | U23: =+E23-Q23 -> 0 | V23: =+G23-R23 -> 0 | W23: =1-S23 -> 0
B24: 01.01.03.02 | C24: ELIMINACION DE MATERIAL EXCEDENTE C/VOLQUETE DE 15M3 (D=10 KM) | D24: m3 | E24: 20.33 | F24: 18.98 | G24: =ROUND(E24*F24,2) -> 385.86 | I24: 20.33 | J24: 385.86 | K24: 1 | N24: =ROUND(M24*$F24,2) -> 0 | O24: =ROUND(N24/$G24,4) -> 0 | Q24: =+I24+M24 -> 20.33 | R24: =+J24+N24 -> 385.86 | S24: =+K24+O24 -> 1 | U24: =+E24-Q24 -> 0 | V24: =+G24-R24 -> 0 | W24: =1-S24 -> 0
B25: 01.01.04 | C25: PLAN DE DESVIO VEHICULAR
B26: 01.01.04.01 | C26: TRANQUERAS DE MADERA 2.40 x 1.20 | D26: und | E26: 2 | F26: 221.35 | G26: =ROUND(E26*F26,2) -> 442.7 | I26: 2 | J26: 442.7 | K26: 1 | N26: =ROUND(M26*$F26,2) -> 0 | O26: =ROUND(N26/$G26,4) -> 0 | Q26: =+I26+M26 -> 2 | R26: =+J26+N26 -> 442.7 | S26: =+K26+O26 -> 1 | U26: =+E26-Q26 -> 0 | V26: =+G26-R26 -> 0 | W26: =1-S26 -> 0
B27: 01.01.04.02 | C27: SEÑALIZACION DE DESVIO DE TRANSITO EN PERIODO DE CONSTRUCCION | D27: GLB | E27: 1 | F27: 221.16 | G27: =ROUND(E27*F27,2) -> 221.16 | I27: 1 | J27: 221.16 | K27: 1 | N27: =ROUND(M27*$F27,2) -> 0 | O27: =ROUND(N27/$G27,4) -> 0 | Q27: =+I27+M27 -> 1 | R27: =+J27+N27 -> 221.16 | S27: =+K27+O27 -> 1 | U27: =+E27-Q27 -> 0 | V27: =+G27-R27 -> 0 | W27: =1-S27 -> 0
B28: 01.02 | C28: PAVIMENTO RIGIDO | G28: =ROUND(E28*F28,2) -> 0
B29: 01.02.01 | C29: MOVIMIENTO DE TIERRAS HASTA EL NIVEL DE SUB - RASANTE
B30: 01.02.01.01 | C30: CORTE EN TERRENO NORMAL CON MAQUINARIA | D30: m3 | E30: 590.54 | F30: 10.47 | G30: =ROUND(E30*F30,2) -> 6182.95 | I30: 590.54 | J30: 6182.95 | K30: 1 | N30: =ROUND(M30*$F30,2) -> 0 | O30: =ROUND(N30/$G30,4) -> 0 | Q30: =+I30+M30 -> 590.54 | R30: =+J30+N30 -> 6182.95 | S30: =+K30+O30 -> 1 | U30: =+E30-Q30 -> 0 | V30: =+G30-R30 -> 0 | W30: =1-S30 -> 0
B31: 01.02.01.02 | C31: RELLENO COMPACTACION CON MATERIAL PROPIO SELECCIONADO | D31: m3 | E31: 51.64 | F31: 19.04 | G31: =ROUND(E31*F31,2) -> 983.23 | I31: 51.64 | J31: 983.23 | K31: 1 | N31: =ROUND(M31*$F31,2) -> 0 | O31: =ROUND(N31/$G31,4) -> 0 | Q31: =+I31+M31 -> 51.64 | R31: =+J31+N31 -> 983.23 | S31: =+K31+O31 -> 1 | U31: =+E31-Q31 -> 0 | V31: =+G31-R31 -> 0 | W31: =1-S31 -> 0
B32: 01.02.01.03 | C32: ELIMINACION DE MATERIAL EXCEDENTE C/VOLQUETE DE 15M3 (D=10KM) | D32: m3 | E32: 738.18 | F32: 18.98 | G32: =ROUND(E32*F32,2) -> 14010.66 | I32: 738.18 | J32: 14010.66 | K32: 1 | N32: =ROUND(M32*$F32,2) -> 0 | O32: =ROUND(N32/$G32,4) -> 0 | Q32: =+I32+M32 -> 738.18 | R32: =+J32+N32 -> 14010.66 | S32: =+K32+O32 -> 1 | U32: =+E32-Q32 -> 0 | V32: =+G32-R32 -> 0 | W32: =1-S32 -> 0
B33: 01.02.02 | C33: BASE | G33: =ROUND(E33*F33,2) -> 0
B34: 01.02.02.01 | C34: CONFORMACION DE BASE MATERIAL MEZCLADO E=0.20m | D34: m2 | E34: 910.14 | F34: 31.15 | G34: =ROUND(E34*F34,2) -> 28350.86 | I34: 910.14 | J34: 28350.86 | K34: 1 | N34: =ROUND(M34*$F34,2) -> 0 | O34: =ROUND(N34/$G34,4) -> 0 | Q34: =+I34+M34 -> 910.14 | R34: =+J34+N34 -> 28350.86 | S34: =+K34+O34 -> 1 | U34: =+E34-Q34 -> 0 | V34: =+G34-R34 -> 0 | W34: =1-S34 -> 0
B35: 01.02.03 | C35: SUB RASANTE | G35: =ROUND(E35*F35,2) -> 0
B36: 01.02.03.01 | C36: PERFILADO, RIEGO Y COMPACTACIÓN DE SUBRASANTE | D36: m2 | E36: 910.14 | F36: 5.54 | G36: =ROUND(E36*F36,2) -> 5042.18 | I36: 910.14 | J36: 5042.18 | K36: 1 | N36: =ROUND(M36*$F36,2) -> 0 | O36: =ROUND(N36/$G36,4) -> 0 | Q36: =+I36+M36 -> 910.14 | R36: =+J36+N36 -> 5042.18 | S36: =+K36+O36 -> 1 | U36: =+E36-Q36 -> 0 | V36: =+G36-R36 -> 0 | W36: =1-S36 -> 0
B37: 01.02.04 | C37: OBRAS DE CONCRETO | G37: =ROUND(E37*F37,2) -> 0
B38: 01.02.04.01 | C38: ENCOFRADO Y DESENCOFRADO EN PAVIMENTOS | D38: m2 | E38: 127.29 | F38: 63.41 | G38: =ROUND(E38*F38,2) -> 8071.46 | I38: 127.29 | J38: 8071.46 | K38: 1 | N38: =ROUND(M38*$F38,2) -> 0 | O38: =ROUND(N38/$G38,4) -> 0 | Q38: =+I38+M38 -> 127.29 | R38: =+J38+N38 -> 8071.46 | S38: =+K38+O38 -> 1 | U38: =+E38-Q38 -> 0 | V38: =+G38-R38 -> 0 | W38: =1-S38 -> 0
B39: 01.02.04.02 | C39: CONCRETO F'C =210 KG/CM2 EN VIA E=15CM | D39: m2 | E39: 910.14 | F39: 119.99 | G39: =ROUND(E39*F39,2) -> 109207.7 | I39: 910.14 | J39: 109207.7 | K39: 1 | N39: =ROUND(M39*$F39,2) -> 0 | O39: =ROUND(N39/$G39,4) -> 0 | Q39: =+I39+M39 -> 910.14 | R39: =+J39+N39 -> 109207.7 | S39: =+K39+O39 -> 1 | U39: =+E39-Q39 -> 0 | V39: =+G39-R39 -> 0 | W39: =1-S39 -> 0
B40: 01.02.04.03 | C40: CURADO DE CONCRETO | D40: m2 | E40: 910.14 | F40: 2.92 | G40: =ROUND(E40*F40,2) -> 2657.61 | I40: 910.14 | J40: 2657.61 | K40: 1 | N40: =ROUND(M40*$F40,2) -> 0 | O40: =ROUND(N40/$G40,4) -> 0 | Q40: =+I40+M40 -> 910.14 | R40: =+J40+N40 -> 2657.61 | S40: =+K40+O40 -> 1 | U40: =+E40-Q40 -> 0 | V40: =+G40-R40 -> 0 | W40: =1-S40 -> 0
B41: 01.02.04.04 | C41: ACERO FY = 4200Kg/cm2 EN JUNTAS DE DILATACION LONGITUDINAL Ø 3/8" | D41: kg | E41: 80.64 | F41: 12.14 | G41: =ROUND(E41*F41,2) -> 978.97 | I41: 80.64 | J41: 978.97 | K41: 1 | N41: =ROUND(M41*$F41,2) -> 0 | O41: =ROUND(N41/$G41,4) -> 0 | Q41: =+I41+M41 -> 80.64 | R41: =+J41+N41 -> 978.97 | S41: =+K41+O41 -> 1 | U41: =+E41-Q41 -> 0 | V41: =+G41-R41 -> 0 | W41: =1-S41 -> 0
...

Sheet PROG VS. EJEC
B1: AVANCE PROGRAMADO VS. EJECUTADO (JULIO 2026)
B2: Obra: | C2: =+FT!$E$5 -> "MEJORAMIENTO Y AMPLIACIÓN DE LOS SERVICIOS DE TRANSITABILIDAD VEHICULAR Y PEATONAL DEL JR LOS PINOS Y JR LOS CEDROS EN CAYHUAYNA Y CAYHUAYNA DEL DISTRITO DE PILLCO MARCA - PROVINCIA DE HUÁNUCO - DEPARTAMENTO DE HUÁNUCO" con CUI N°2536252
B3: Entidad: | C3: =+FT!$E$4 -> MUNICIPALIDAD DISTRITAL DE PILLCO MARCA
B4: Ejecutor: | C4: =+FT!$E$15 -> CONSORCIO EJECUTOR LOS PINOS
B5: Supervisor: | C5: =+FT!$E$34 -> PROYECTA PCL S.A.C | D5: VALOR REFERENCIAL (CON IGV) | G5: =+FT!$E$24 -> 638827.47
B6: Residente: | C6: =+FT!$E$32 -> ING. RAMIREZ BLANCO GABRIEL AUGUSTO HERMOGENES | D6: MONTO DEL CONTRATO (INCL. IGV): | G6: =+FT!$E$25 -> 638827.47
B7: Ing. Supervisor: | C7: =+FT!$E$46 -> ING. CESAR RICARDO ZELADA RODRIGUEZ (CIP N° 98469) | D7: PLAZO DE EJECUCIÓN: | G7: =+FT!$E$31 -> SESENTA (60) DÍAS CALENDARIOS
B9: ITEM | C9: DESCRIPCION | D9: PRESUPUESTO DE OBRA | I9: 46204 | L9: 46204
I10: 46204 | J10: 46234 | L10: 46204 | M10: 46234
D11: UND | E11: METRADO | F11: P.UND | G11: TOTAL | I11: PORCEN. (%) | J11: COSTO (S/) | L11: PORCEN. (%) | M11: COSTO (S/)
B12: 01 | C12: CREACION DE PISTAS Y VEREDAS JR LOS CEDROS
B13: 01.01 | C13: OBRAS PROVISIONALES Y TRABAJOS PRELIMINARES
B14: 01.01.01 | C14: OBRAS PROVISIONALES
B15: 01.01.01.01 | C15: ALQUILER DE ALAMACEN, OFICINA Y CASETA DE GUARDIANIA | D15: mes | E15: 2 | F15: 2400 | G15: =ROUND(E15*F15,2) -> 4800 | I15: =ROUND(J15/$G15,4) -> 0.3333 | J15: 1600 | L15: 1 | M15: 1152
B16: 01.01.01.02 | C16: CARTEL DE IDENTIFICACION DE LA OBRA DE 3.60 x 4.80 m (SOPORTE DE MADERA) | D16: und | E16: 1 | F16: 1205.49 | G16: =ROUND(E16*F16,2) -> 1205.49 | I16: =ROUND(J16/$G16,4) -> 0 | L16: 1 | M16: 0
B17: 01.01.01.03 | C17: ALQUILER DE BAÑOS PORTATILES Y LAVADERO | D17: mes | E17: 2 | F17: 850 | G17: =ROUND(E17*F17,2) -> 1700 | I17: =ROUND(J17/$G17,4) -> 0.5167 | J17: 878.33333 | L17: 1 | M17: 408
B18: 01.01.02 | C18: TRABAJOS PRELIMINARES | G18: =ROUND(E18*F18,2) -> 0
B19: 01.01.02.01 | C19: LIMPIEZA DE TERRENO MANUAL | D19: m2 | E19: 1932.21 | F19: 1.06 | G19: =ROUND(E19*F19,2) -> 2048.14 | I19: =ROUND(J19/$G19,4) -> 0 | L19: 1932.21 | M19: 0
B20: 01.01.02.02 | C20: TRAZO Y REPLANTEO EN TERRENO NORMAL | D20: m2 | E20: 1932.21 | F20: 4.32 | G20: =ROUND(E20*F20,2) -> 8347.15 | I20: =ROUND(J20/$G20,4) -> 0.4539 | J20: 3789.15 | L20: 1932.21 | M20: 0
B21: 01.01.02.03 | C21: MOVILIZACION Y DESMOVILIZACION DE MAQUINARIA Y EQUIPO | D21: GLB | E21: 1 | F21: 2500 | G21: =ROUND(E21*F21,2) -> 2500 | I21: =ROUND(J21/$G21,4) -> 0 | L21: 1 | M21: 0
B22: 01.01.03 | C22: DEMOLICIONES | G22: =ROUND(E22*F22,2) -> 0
B23: 01.01.03.01 | C23: DEMOLICION DE VEREDAS EXISTENTES DE 0.10M | D23: m2 | E23: 135.5 | F23: 21.33 | G23: =ROUND(E23*F23,2) -> 2890.22 | I23: =ROUND(J23/$G23,4) -> 0 | L23: 135.5 | M23: 0
B24: 01.01.03.02 | C24: ELIMINACION DE MATERIAL EXCEDENTE C/VOLQUETE DE 15M3 (D=10 KM) | D24: m3 | E24: 20.33 | F24: 18.98 | G24: =ROUND(E24*F24,2) -> 385.86 | I24: =ROUND(J24/$G24,4) -> 0 | L24: 20.33 | M24: 0
B25: 01.01.04 | C25: PLAN DE DESVIO VEHICULAR
B26: 01.01.04.01 | C26: TRANQUERAS DE MADERA 2.40 x 1.20 | D26: und | E26: 2 | F26: 221.35 | G26: =ROUND(E26*F26,2) -> 442.7 | I26: =ROUND(J26/$G26,4) -> 0 | L26: 2 | M26: 0
B27: 01.01.04.02 | C27: SEÑALIZACION DE DESVIO DE TRANSITO EN PERIODO DE CONSTRUCCION | D27: GLB | E27: 1 | F27: 221.16 | G27: =ROUND(E27*F27,2) -> 221.16 | I27: =ROUND(J27/$G27,4) -> 0 | L27: 1 | M27: 0
B28: 01.02 | C28: PAVIMENTO RIGIDO | G28: =ROUND(E28*F28,2) -> 0
B29: 01.02.01 | C29: MOVIMIENTO DE TIERRAS HASTA EL NIVEL DE SUB - RASANTE
B30: 01.02.01.01 | C30: CORTE EN TERRENO NORMAL CON MAQUINARIA | D30: m3 | E30: 590.54 | F30: 10.47 | G30: =ROUND(E30*F30,2) -> 6182.95 | I30: =ROUND(J30/$G30,4) -> 0 | L30: 590.54 | M30: 0
B31: 01.02.01.02 | C31: RELLENO COMPACTACION CON MATERIAL PROPIO SELECCIONADO | D31: m3 | E31: 51.64 | F31: 19.04 | G31: =ROUND(E31*F31,2) -> 983.23 | I31: =ROUND(J31/$G31,4) -> 0 | L31: 51.64 | M31: 0
B32: 01.02.01.03 | C32: ELIMINACION DE MATERIAL EXCEDENTE C/VOLQUETE DE 15M3 (D=10KM) | D32: m3 | E32: 738.18 | F32: 18.98 | G32: =ROUND(E32*F32,2) -> 14010.66 | I32: =ROUND(J32/$G32,4) -> 1 | J32: 14010.66 | L32: 738.18 | M32: 0
B33: 01.02.02 | C33: BASE | G33: =ROUND(E33*F33,2) -> 0
B34: 01.02.02.01 | C34: CONFORMACION DE BASE MATERIAL MEZCLADO E=0.20m | D34: m2 | E34: 910.14 | F34: 31.15 | G34: =ROUND(E34*F34,2) -> 28350.86 | I34: =ROUND(J34/$G34,4) -> 0 | L34: 910.14 | M34: 0
B35: 01.02.03 | C35: SUB RASANTE | G35: =ROUND(E35*F35,2) -> 0
B36: 01.02.03.01 | C36: PERFILADO, RIEGO Y COMPACTACIÓN DE SUBRASANTE | D36: m2 | E36: 910.14 | F36: 5.54 | G36: =ROUND(E36*F36,2) -> 5042.18 | I36: =ROUND(J36/$G36,4) -> 0 | L36: 910.14 | M36: 0
B37: 01.02.04 | C37: OBRAS DE CONCRETO | G37: =ROUND(E37*F37,2) -> 0
B38: 01.02.04.01 | C38: ENCOFRADO Y DESENCOFRADO EN PAVIMENTOS | D38: m2 | E38: 127.29 | F38: 63.41 | G38: =ROUND(E38*F38,2) -> 8071.46 | I38: =ROUND(J38/$G38,4) -> 0 | L38: 127.29 | M38: 0
B39: 01.02.04.02 | C39: CONCRETO F'C =210 KG/CM2 EN VIA E=15CM | D39: m2 | E39: 910.14 | F39: 119.99 | G39: =ROUND(E39*F39,2) -> 109207.7 | I39: =ROUND(J39/$G39,4) -> 0.9213 | J39: 100614.38 | L39: 910.14 | M39: 0
B40: 01.02.04.03 | C40: CURADO DE CONCRETO | D40: m2 | E40: 910.14 | F40: 2.92 | G40: =ROUND(E40*F40,2) -> 2657.61 | I40: =ROUND(J40/$G40,4) -> 1 | J40: 2657.61 | L40: 910.14 | M40: 0
B41: 01.02.04.04 | C41: ACERO FY = 4200Kg/cm2 EN JUNTAS DE DILATACION LONGITUDINAL Ø 3/8" | D41: kg | E41: 80.64 | F41: 12.14 | G41: =ROUND(E41*F41,2) -> 978.97 | I41: =ROUND(J41/$G41,4) -> 0 | L41: 80.64 | M41: 0
...

Sheet CONTROL GEN. AVAN. OBRA.
B1: CONTROL GENERAL DE AVANCE DE OBRA
B2: Obra: | C2: =+FT!$E$5 -> "MEJORAMIENTO Y AMPLIACIÓN DE LOS SERVICIOS DE TRANSITABILIDAD VEHICULAR Y PEATONAL DEL JR LOS PINOS Y JR LOS CEDROS EN CAYHUAYNA Y CAYHUAYNA DEL DISTRITO DE PILLCO MARCA - PROVINCIA DE HUÁNUCO - DEPARTAMENTO DE HUÁNUCO" con CUI N°2536252
B3: Entidad: | C3: =+FT!$E$4 -> MUNICIPALIDAD DISTRITAL DE PILLCO MARCA
B4: Ejecutor: | C4: =+FT!$E$15 -> CONSORCIO EJECUTOR LOS PINOS
B5: Supervisor: | C5: =+FT!$E$34 -> PROYECTA PCL S.A.C | G5: VALOR REFERENCIAL (CON IGV) | I5: =+FT!$E$24 -> 638827.47
B6: Residente: | C6: =+FT!$E$32 -> ING. RAMIREZ BLANCO GABRIEL AUGUSTO HERMOGENES | G6: MONTO DEL CONTRATO (INCL. IGV): | I6: =+FT!$E$25 -> 638827.47
B7: Ing. Supervisor: | C7: =+FT!$E$46 -> ING. CESAR RICARDO ZELADA RODRIGUEZ (CIP N° 98469) | G7: PLAZO DE EJECUCIÓN: | I7: =+FT!$E$31 -> SESENTA (60) DÍAS CALENDARIOS
B9: VALORIZACIÓN | D9: PROGRAMADO | H9: EJECUTADO | L9: EVALUACIÓN DEL ATRASO (80% DEL PROGRAMADO ACUMULADO) | P9: SITUACIÓN DE LA OBRA
B10: Nº | C10: MES | D10: MENSUAL | E10: ACUMULADO | F10: % MENSUAL | G10: % ACUMULADO | H10: MENSUAL | I10: ACUMULADO | J10: % MENSUAL | K10: % ACUMULADO | L10: % PROGRAMADO ACUMULADO | M10: 80% DEL PROGRAMADO ACUMULADO | N10: % EJECUTADO ACUMULADO | O10: CONCLUSIÓN: ATRASO (-) ADELANTO (+) | T10: 131453.71
B11: 1 | C11: =+'CALEN. PROG.'!I9 -> 46174 | D11: =+'CALEN. PROG.'!J161 -> 157550.32 | E11: =D11 -> 157550.32 | F11: =ROUND(D11/$D$14,4) -> 0.2466 | G11: =+F11 -> 0.2466 | H11: =+'CALEN. VALO.'!J161 -> 400648.29 | I11: =+H11 -> 400648.29 | J11: =ROUND(H11/$D$14,4) -> 0.6272 | K11: =+J11 -> 0.6272 | L11: =+G11 -> 0.2466 | M11: =ROUND(L11*0.8,4) -> 0.1973 | N11: =+K11 -> 0.6272 | O11: =+N11-L11 -> 0.3806 | P11: =+IF(K11<G11,"ATRASADA",IF(K11=100%,"CULMINADA","ADELANTADA")) -> ADELANTADA | T11: 122142.92
B12: 2 | C12: =+'CALEN. PROG.'!L9 -> 46204 | D12: =+'CALEN. PROG.'!M161 -> 203396.72 | E12: =+D12+E11 -> 360947.04 | F12: =ROUND(D12/$D$14,4) -> 0.3184 | G12: =+F12+G11 -> 0.565 | H12: =+'CALEN. VALO.'!M161 -> 224198.55 | I12: =+H12+I11 -> 624846.84 | J12: =ROUND(H12/$D$14,4) -> 0.351 | K12: =+J12+K11 -> 0.9782 | L12: =+G12 -> 0.565 | M12: =ROUND(L12*0.8,4) -> 0.452 | N12: =+K12 -> 0.9782 | O12: =+N12-L12 -> 0.4132 | P12: =+IF(K12<G12,"ATRASADA",IF(K12=100%,"CULMINADA","ADELANTADA")) -> ADELANTADA | T12: =SUM(T10:T11) -> 253596.63
B13: 3 | C13: =+'CALEN. PROG.'!O9 -> 46235 | D13: =+'CALEN. PROG.'!P161 -> 277880.43 | E13: =+D13+E12 -> 638827.47 | F13: =ROUND(D13/$D$14,4) -> 0.435 | G13: =+F13+G12 -> 1
B14: TOTAL C/IGV | D14: =SUM(D11:D13) -> 638827.47 | F14: =SUM(F11:F13) -> 1 | H14: =SUM(H11:H12) -> 624846.84 | J14: =SUM(J11:J12) -> 0.9782 | L14: =+L12 -> 0.565 | M14: =+M12 -> 0.452 | N14: =+N12 -> 0.9782 | O14: =+O12 -> 0.4132 | P14: OBRA ADELANTADA

Sheet CURVA S
B1: CURVA S
B2: Obra: | C2: =+FT!$E$5 -> "MEJORAMIENTO Y AMPLIACIÓN DE LOS SERVICIOS DE TRANSITABILIDAD VEHICULAR Y PEATONAL DEL JR LOS PINOS Y JR LOS CEDROS EN CAYHUAYNA Y CAYHUAYNA DEL DISTRITO DE PILLCO MARCA - PROVINCIA DE HUÁNUCO - DEPARTAMENTO DE HUÁNUCO" con CUI N°2536252
B3: Entidad: | C3: =+FT!$E$4 -> MUNICIPALIDAD DISTRITAL DE PILLCO MARCA
B4: Ejecutor: | C4: =+FT!$E$15 -> CONSORCIO EJECUTOR LOS PINOS
B5: Supervisor: | C5: =+FT!$E$34 -> PROYECTA PCL S.A.C | F5: VALOR REFERENCIAL (CON IGV) | H5: =+FT!$E$24 -> 638827.47
B6: Residente: | C6: =+FT!$E$32 -> ING. RAMIREZ BLANCO GABRIEL AUGUSTO HERMOGENES | F6: MONTO DEL CONTRATO (INCL. IGV): | H6: =+FT!$E$25 -> 638827.47
B7: Ing. Supervisor: | C7: =+FT!$E$46 -> ING. CESAR RICARDO ZELADA RODRIGUEZ (CIP N° 98469) | F7: PLAZO DE EJECUCIÓN: | H7: =+FT!$E$31 -> SESENTA (60) DÍAS CALENDARIOS
I31: 0
B32: VALORIZACIÓN | D32: PROGRAMADO | G32: CURVA DEL 80% | H32: EJECUTADO | K32: ESTADO DE LA OBRA
B33: Nº | C33: MES | D33: MONTO | E33: % MENSUAL | F33: %ACUMULADO | H33: MONTO | I33: MENSUAL | J33: ACUMULADO
B34: 0 | E34: 0 | F34: 0 | I34: 0 | J34: 0
B35: 1 | C35: =+'CONTROL GEN. AVAN. OBRA.'!C11 -> 46174 | D35: =+'CONTROL GEN. AVAN. OBRA.'!D11 -> 157550.32 | E35: =ROUND(D35/$D$38,4) -> 0.2466 | F35: =+E35 -> 0.2466 | G35: =0.8*F35 -> 0.19728 | H35: =+'CONTROL GEN. AVAN. OBRA.'!H11 -> 400648.29 | I35: =ROUND(H35/$D$38,4) -> 0.6272 | J35: =+I35 -> 0.6272 | K35: =+'CONTROL GEN. AVAN. OBRA.'!P11 -> ADELANTADA
B36: 2 | C36: =+'CONTROL GEN. AVAN. OBRA.'!C12 -> 46204 | D36: =+'CONTROL GEN. AVAN. OBRA.'!D12 -> 203396.72 | E36: =ROUND(D36/$D$38,4) -> 0.3184 | F36: =+E36+F35 -> 0.565 | G36: =0.8*F36 -> 0.452 | H36: =+'CONTROL GEN. AVAN. OBRA.'!H12 -> 224198.55 | I36: =ROUND(H36/$D$38,4) -> 0.351 | J36: =+I36+J35 -> 0.9782 | K36: =+'CONTROL GEN. AVAN. OBRA.'!P12 -> ADELANTADA
B37: 3 | C37: =+'CONTROL GEN. AVAN. OBRA.'!C13 -> 46235 | D37: =+'CONTROL GEN. AVAN. OBRA.'!D13 -> 277880.43 | E37: =ROUND(D37/$D$38,4) -> 0.435 | F37: =+E37+F36 -> 1 | G37: =0.8*F37 -> 0.8
B38: TOTAL | D38: =SUM(D35:D37) -> 638827.47 | E38: =SUM(E35:E37) -> 1 | H38: =SUM(H35:H36) -> 624846.84 | I38: =SUM(I35:I36) -> 0.9782 | K38: =+'CONTROL GEN. AVAN. OBRA.'!P14 -> OBRA ADELANTADA

Sheet CONTROL AVAN. FISICO
B1: CONTROL DE AVANCE FÍSICO DE OBRA
B2: Obra: | C2: =+FT!$E$5 -> "MEJORAMIENTO Y AMPLIACIÓN DE LOS SERVICIOS DE TRANSITABILIDAD VEHICULAR Y PEATONAL DEL JR LOS PINOS Y JR LOS CEDROS EN CAYHUAYNA Y CAYHUAYNA DEL DISTRITO DE PILLCO MARCA - PROVINCIA DE HUÁNUCO - DEPARTAMENTO DE HUÁNUCO" con CUI N°2536252
B3: Entidad: | C3: =+FT!$E$4 -> MUNICIPALIDAD DISTRITAL DE PILLCO MARCA
B4: Ejecutor: | C4: =+FT!$E$15 -> CONSORCIO EJECUTOR LOS PINOS
B5: Supervisor: | C5: =+FT!$E$34 -> PROYECTA PCL S.A.C
B6: Residente: | C6: =+FT!$E$32 -> ING. RAMIREZ BLANCO GABRIEL AUGUSTO HERMOGENES | F6: MONTO DEL CONTRATO ORIGINAL: | H6: =+FT!$E$25 -> 638827.47 | I6: INCL. IGV | J6: que representa el | K6: 1
B7: Ing. Supervisor: | C7: =+FT!$E$46 -> ING. CESAR RICARDO ZELADA RODRIGUEZ (CIP N° 98469) | F7: MONTO DEL CONTRATO VIGENTE: | H7: =+H6 -> 638827.47 | I7: INCL. IGV | J7: que representa el | K7: =+K6 -> 1
B9: AVANCE FÍSICO
B10: N° | C10: MES | D10: MONTO | E10: % MENSUAL
B11: VAL. N°01 | C11: =+'CONTROL GEN. AVAN. OBRA.'!C11 -> 46174 | D11: =+'CONTROL GEN. AVAN. OBRA.'!H11 -> 400648.29 | E11: =+'CONTROL GEN. AVAN. OBRA.'!J11 -> 0.6272
B12: VAL. N°02 | C12: =+'CONTROL GEN. AVAN. OBRA.'!C12 -> 46204 | D12: =+'CONTROL GEN. AVAN. OBRA.'!H12 -> 224198.55 | E12: =+'CONTROL GEN. AVAN. OBRA.'!J12 -> 0.351
B13: VAL. N°03 | C13: =+'CONTROL GEN. AVAN. OBRA.'!C13 -> 46235
B14: ACUMULADO | D14: =SUM(D11:D12) -> 624846.84 | E14: =SUM(E11:E12) -> 0.9782
B15: SALDO | D15: =+H6-D14 -> 13980.63 | E15: =1-E14 -> 0.0218
B18: ='CURVA S'!B32 -> VALORIZACIÓN | C18: ='CURVA S'!C32 -> 0 | D18: ='CURVA S'!D32 -> PROGRAMADO | E18: ='CURVA S'!E32 -> 0 | F18: ='CURVA S'!F32 -> 0 | G18: ='CURVA S'!G32 -> CURVA DEL 80% | H18: ='CURVA S'!H32 -> EJECUTADO | I18: ='CURVA S'!I32 -> 0 | ... K18: ='CURVA S'!K32 -> ESTADO DE LA OBRA
B19: ='CURVA S'!B33 -> Nº | C19: ='CURVA S'!C33 -> MES | D19: ='CURVA S'!D33 -> MONTO | E19: ='CURVA S'!E33 -> % MENSUAL | F19: ='CURVA S'!F33 -> %ACUMULADO | G19: ='CURVA S'!G33 -> 0 | H19: ='CURVA S'!H33 -> MONTO | I19: ='CURVA S'!I33 -> MENSUAL | ... K19: ='CURVA S'!K33 -> 0
B20: ='CURVA S'!B35 -> 1 | C20: ='CURVA S'!C35 -> 46174 | D20: ='CURVA S'!D35 -> 157550.32 | E20: ='CURVA S'!E35 -> 0.2466 | F20: ='CURVA S'!F35 -> 0.2466 | G20: ='CURVA S'!G35 -> 0.19728 | H20: ='CURVA S'!H35 -> 400648.29 | I20: ='CURVA S'!I35 -> 0.6272 | ... K20: ='CURVA S'!K35 -> ADELANTADA
B21: ='CURVA S'!B36 -> 2 | C21: ='CURVA S'!C36 -> 46204 | D21: ='CURVA S'!D36 -> 203396.72 | E21: ='CURVA S'!E36 -> 0.3184 | F21: ='CURVA S'!F36 -> 0.565 | G21: ='CURVA S'!G36 -> 0.452 | H21: ='CURVA S'!H36 -> 224198.55 | I21: ='CURVA S'!I36 -> 0.351 | ... K21: ='CURVA S'!K36 -> ADELANTADA
B22: ='CURVA S'!B37 -> 3 | C22: ='CURVA S'!C37 -> 46235 | D22: ='CURVA S'!D37 -> 277880.43 | E22: ='CURVA S'!E37 -> 0.435 | F22: ='CURVA S'!F37 -> 1 | G22: ='CURVA S'!G37 -> 0.8
B23: ='CURVA S'!B38 -> TOTAL | D23: ='CURVA S'!D38 -> 638827.47 | E23: ='CURVA S'!E38 -> 1 | H23: ='CURVA S'!H38 -> 624846.84 | I23: ='CURVA S'!I38 -> 0.9782 | K23: ='CURVA S'!K38 -> OBRA ADELANTADA

Sheet CONTROL FINANCIERO
B1: CONTROL DE AVANCE FINANCIERO DE OBRA
B2: Obra: | C2: =+FT!$E$5 -> "MEJORAMIENTO Y AMPLIACIÓN DE LOS SERVICIOS DE TRANSITABILIDAD VEHICULAR Y PEATONAL DEL JR LOS PINOS Y JR LOS CEDROS EN CAYHUAYNA Y CAYHUAYNA DEL DISTRITO DE PILLCO MARCA - PROVINCIA DE HUÁNUCO - DEPARTAMENTO DE HUÁNUCO" con CUI N°2536252
B3: Entidad: | C3: =+FT!$E$4 -> MUNICIPALIDAD DISTRITAL DE PILLCO MARCA
B4: Ejecutor: | C4: =+FT!$E$15 -> CONSORCIO EJECUTOR LOS PINOS
B5: Supervisor: | C5: =+FT!$E$34 -> PROYECTA PCL S.A.C
B6: Residente: | C6: =+FT!$E$32 -> ING. RAMIREZ BLANCO GABRIEL AUGUSTO HERMOGENES | E6: MONTO DEL CONTRATO ORIGINAL: | F6: =+FT!$E$25 -> 638827.47 | G6: INCL. IGV
B7: Ing. Supervisor: | C7: =+FT!$E$46 -> ING. CESAR RICARDO ZELADA RODRIGUEZ (CIP N° 98469) | E7: MONTO DEL CONTRATO VIGENTE: | F7: =+F6 -> 638827.47 | G7: INCL. IGV
B9: N° | C9: Periodo | D9: Monto Facturables | E9: Montos Devengados | G9: Montos Pendientes por devengar
E10: Montos | F10: %
B11: A. Adelantos otorgados
B12: Adelanto directo | C12: - | D12: 0 | E12: =+D12 -> 0 | F12: =+E12/$F$6 -> 0 | G12: 0
B13: Adelanto de materiales | C13: - | D13: 0 | E13: =+D13 -> 0 | F13: =+E13/$F$6 -> 0 | G13: 0
B14: B. Valorizaciones de obra
B15: Valorización N°01 | C15: 46174 | D15: =+'CONTROL GEN. AVAN. OBRA.'!H11 -> 400648.29 | E15: =+D15 -> 400648.29 | F15: =+E15/$F$6 -> 0.62716196 | G15: =+D15-E15 -> 0
B16: Valorización N°02 | C16: 46204 | D16: =+'CONTROL GEN. AVAN. OBRA.'!H12 -> 224198.55 | E16: 0 | F16: =+E16/$F$6 -> 0 | G16: =+D16-E16 -> 224198.55
B17: Valorización N°03 | C17: 46235
B19: ACUMULADO | D19: =SUM(D12:D18) -> 624846.84 | E19: =SUM(E12:E18) -> 400648.29 | F19: =SUM(F12:F18) -> 0.62716196 | G19: =SUM(G12:G18) -> 224198.55
B20: SALDO | D20: =$F$7-D19 -> 13980.63 | E20: =$F$7-E19 -> 238179.18 | F20: =1-F19 -> 0.37283804 | G20: =+D20 -> 13980.63

Sheet RESUMEN VAL.
B1: RESUMEN DE VALORIZACIÓN POR COMPONENTES
B2: =+FT!E20 -> CONTRATO DE EJECUCIÓN DE OBRA N°004-2026-MDPM/GM
B3: Obra: | C3: =+FT!$E$5 -> "MEJORAMIENTO Y AMPLIACIÓN DE LOS SERVICIOS DE TRANSITABILIDAD VEHICULAR Y PEATONAL DEL JR LOS PINOS Y JR LOS CEDROS EN CAYHUAYNA Y CAYHUAYNA DEL DISTRITO DE PILLCO MARCA - PROVINCIA DE HUÁNUCO - DEPARTAMENTO DE HUÁNUCO" con CUI N°2536252
B4: Entidad: | C4: =+FT!$E$4 -> MUNICIPALIDAD DISTRITAL DE PILLCO MARCA
B5: Ejecutor: | C5: =+FT!$E$15 -> CONSORCIO EJECUTOR LOS PINOS
B6: Supervisor: | C6: =+FT!$E$34 -> PROYECTA PCL S.A.C
B7: Residente: | C7: =+FT!$E$32 -> ING. RAMIREZ BLANCO GABRIEL AUGUSTO HERMOGENES
B8: Ing. Supervisor: | C8: =+FT!$E$46 -> ING. CESAR RICARDO ZELADA RODRIGUEZ (CIP N° 98469)
B10: ÍTEM | C10: DESCRIPCIÓN | E10: MONTO CONTRATADO | G10: ACUMULADO ANTERIOR | J10: ACTUAL | M10: ACUMULADO ACTUAL | P10: SALDO
G11: % DE AVANCE | H11: MONTO | J11: % DE AVANCE | K11: MONTO | M11: % DE AVANCE | N11: MONTO | P11: % DE SALDO | Q11: MONTO
B12: =+'VAL. MENSUAL'!B13 -> 01.01 | C12: =+'VAL. MENSUAL'!C13 -> OBRAS PROVISIONALES Y TRABAJOS PRELIMINARES | E12: =SUM('VAL. MENSUAL'!G13:G27) -> 24540.72 | G12: =ROUND(H12/$E12,4) -> 0.8676 | H12: =SUM('VAL. MENSUAL'!J13:J27) -> 21290.72 | J12: =ROUND(K12/$E12,4) -> 0.0636 | K12: =SUM('VAL. MENSUAL'!N13:N27) -> 1560 | M12: =+G12+J12 -> 0.9312 | N12: =H12+K12 -> 22850.72 | P12: =1-M12 -> 0.0688 | Q12: =E12-N12 -> 1690
B13: =+'VAL. MENSUAL'!B28 -> 01.02 | C13: =+'VAL. MENSUAL'!C28 -> PAVIMENTO RIGIDO | E13: =SUM('VAL. MENSUAL'!G28:G51) -> 195936.33 | G13: =ROUND(H13/$E13,4) -> 0.9737 | H13: =SUM('VAL. MENSUAL'!J28:J51) -> 190783.92 | J13: =ROUND(K13/$E13,4) -> 0 | K13: =SUM('VAL. MENSUAL'!N28:N51) -> 0 | M13: =+G13+J13 -> 0.9737 | N13: =H13+K13 -> 190783.92 | P13: =1-M13 -> 0.0263 | Q13: =E13-N13 -> 5152.41
B14: =+'VAL. MENSUAL'!B52 -> 01.03 | C14: =+'VAL. MENSUAL'!C52 -> VEREDAS, RAMPAS Y MARTILLOS | E14: =SUM('VAL. MENSUAL'!G52:G77) -> 81286.85 | G14: =ROUND(H14/$E14,4) -> 0.3738 | H14: =SUM('VAL. MENSUAL'!J52:J77) -> 30386.06 | J14: =ROUND(K14/$E14,4) -> 0.6262 | K14: =SUM('VAL. MENSUAL'!N52:N77) -> 50900.79 | M14: =+G14+J14 -> 1 | N14: =H14+K14 -> 81286.85 | P14: =1-M14 -> 0 | Q14: =E14-N14 -> 0
B15: =+'VAL. MENSUAL'!B78 -> 01.04 | C15: =+'VAL. MENSUAL'!C78 -> CUNETA PLUVIAL | E15: =SUM('VAL. MENSUAL'!G78:G89) -> 22284.83 | G15: =ROUND(H15/$E15,4) -> 0 | H15: =SUM('VAL. MENSUAL'!J78:J89) -> 0 | J15: =ROUND(K15/$E15,4) -> 1 | K15: =SUM('VAL. MENSUAL'!N78:N89) -> 22284.83 | M15: =+G15+J15 -> 1 | N15: =H15+K15 -> 22284.83 | P15: =1-M15 -> 0 | Q15: =E15-N15 -> 0
B16: =+'VAL. MENSUAL'!B90 -> 01.05 | C16: =+'VAL. MENSUAL'!C90 -> SARDINELES DE CONCRETO | E16: =SUM('VAL. MENSUAL'!G90:G101) -> 41213.67 | G16: =ROUND(H16/$E16,4) -> 0 | H16: =SUM('VAL. MENSUAL'!J90:J101) -> 0 | J16: =ROUND(K16/$E16,4) -> 1 | K16: =SUM('VAL. MENSUAL'!N90:N101) -> 41213.67 | M16: =+G16+J16 -> 1 | N16: =H16+K16 -> 41213.67 | P16: =1-M16 -> 0 | Q16: =E16-N16 -> 0
B17: =+'VAL. MENSUAL'!B102 -> 01.06 | C17: =+'VAL. MENSUAL'!C102 -> MURO DE CONTENCION | E17: =SUM('VAL. MENSUAL'!G102:G122) -> 18738.92 | G17: =ROUND(H17/$E17,4) -> 0 | H17: =SUM('VAL. MENSUAL'!J102:J122) -> 0 | J17: =ROUND(K17/$E17,4) -> 1 | K17: =SUM('VAL. MENSUAL'!N102:N122) -> 18738.92 | M17: =+G17+J17 -> 1 | N17: =H17+K17 -> 18738.92 | P17: =1-M17 -> 0 | Q17: =E17-N17 -> 0
B18: =+'VAL. MENSUAL'!B123 -> 01.07 | C18: =+'VAL. MENSUAL'!C123 -> GRADERIAS | E18: =SUM('VAL. MENSUAL'!G123:G133) -> 6001.05 | G18: =ROUND(H18/$E18,4) -> 0.3717 | H18: =SUM('VAL. MENSUAL'!J123:J133) -> 2230.76 | J18: =ROUND(K18/$E18,4) -> 0.6283 | K18: =SUM('VAL. MENSUAL'!N123:N133) -> 3770.29 | M18: =+G18+J18 -> 1 | N18: =H18+K18 -> 6001.05 | P18: =1-M18 -> 0 | Q18: =E18-N18 -> 0
B19: =+'VAL. MENSUAL'!B134 -> 01.08 | C19: =+'VAL. MENSUAL'!C134 -> JARDINERIA | E19: =SUM('VAL. MENSUAL'!G134:G136) -> 18254.61 | G19: =ROUND(H19/$E19,4) -> 0 | H19: =SUM('VAL. MENSUAL'!J134:J136) -> 0 | J19: =ROUND(K19/$E19,4) -> 1 | K19: =SUM('VAL. MENSUAL'!N134:N136) -> 18254.61 | M19: =+G19+J19 -> 1 | N19: =H19+K19 -> 18254.61 | P19: =1-M19 -> 0 | Q19: =E19-N19 -> 0
B20: =+'VAL. MENSUAL'!B137 -> 01.09 | C20: =+'VAL. MENSUAL'!C137 -> PLANTAS DECORATIVAS | E20: =SUM('VAL. MENSUAL'!G137:G138) -> 1224 | H20: =SUM('VAL. MENSUAL'!J137:J138) -> 0 | K20: =SUM('VAL. MENSUAL'!N137:N138) -> 1224 | M20: =+G20+J20 -> 0 | N20: =H20+K20 -> 1224 | P20: =1-M20 -> 1 | Q20: =E20-N20 -> 0
B21: =+'VAL. MENSUAL'!B139 -> 01.10 | C21: =+'VAL. MENSUAL'!C139 -> OTROS | E21: =SUM('VAL. MENSUAL'!G139:G140) -> 10200 | H21: =SUM('VAL. MENSUAL'!J139:J140) -> 10200 | K21: =SUM('VAL. MENSUAL'!N139:N140) -> 0 | M21: =+G21+J21 -> 0 | N21: =H21+K21 -> 10200 | P21: =1-M21 -> 1 | Q21: =E21-N21 -> 0
B22: =+'VAL. MENSUAL'!B141 -> 01.11 | C22: =+'VAL. MENSUAL'!C141 -> SEGURIDAD Y SALUD | E22: =SUM('VAL. MENSUAL'!F141:F146) -> 18340.56 | H22: =SUM('VAL. MENSUAL'!I141:I146) -> 4.3 | K22: =SUM('VAL. MENSUAL'!N141:N146) -> 840 | M22: =+G22+J22 -> 0 | N22: =H22+K22 -> 844.3 | P22: =1-M22 -> 1 | Q22: =E22-N22 -> 17496.26
B23: =+'VAL. MENSUAL'!B147 -> 01.12 | C23: =+'VAL. MENSUAL'!C147 -> FLETE | E23: =SUM('VAL. MENSUAL'!G147:G148) -> 6023 | H23: =SUM('VAL. MENSUAL'!J147:J148) -> 6023 | K23: =SUM('VAL. MENSUAL'!N147:N148) -> 0 | M23: =+G23+J23 -> 0 | N23: =H23+K23 -> 6023 | P23: =1-M23 -> 1 | Q23: =E23-N23 -> 0
